Workbook

Sheet Entry
A1: Price (strike prices below value) | D1: Weight | E1: Long | F1: Immediate
A2: =A8-MOD(A8,50) -> 24550 | D2: =D3-50 -> 24350 | E2: 1 | F2: 0
A3: PCR | D3: =D4-50 -> 24400 | E3: 2 | F3: 0
A4: =SUM('Data Dump'!V:V)/SUM('Data Dump'!B:B) -> #N/A | B4: 1 | D4: =D5-50 -> 24450 | E4: 4 | F4: 0
D5: =D6-50 -> 24500 | E5: 11 | F5: 15
A6: 7 | D6: =A2 -> 24550 | E6: 32 | F6: 35
A7: Current Price | D7: =D6+50 -> 24600 | E7: 32 | F7: 35
A8: 24568 | D8: =D7+50 -> 24650 | E8: 11 | F8: 15
A9: SD | B9: VIX | D9: =D8+50 -> 24700 | E9: 4 | F9: 0
A10: 0.23 | B10: 0.145 | D10: =D9+50 -> 24750 | E10: 2 | F10: 0
A11: VIX Weekly | D11: =D10+50 -> 24800 | E11: 1 | F11: 0
A12: =B10/SQRT(52) -> 0.020107882
A13: Vix Daily
A14: =B10/SQRT(255) -> 0.0090802522
A15: Intrest rate
A16: 0.07
A17: Time of expiry
A18: =(5-WEEKDAY(TODAY())+1)/365 -> 0.0082191781
A19: 1 yr return
A20: 0.2369
A21: Divident
A22: 0.0125
A23: IV
A24: =(AVERAGE('Data Dump'!E:E)+AVERAGE('Data Dump'!S:S))/2 -> #N/A | B24: 6.06

Sheet Sheet1
B2: Cookies
B3: _ga=GA1.1.368949583.1715016028; _ga_QJZ4447QD3=GS1.1.1716713387.2.0.1716713387.0.0.0; AKA_A2=A; defaultLang=en; ak_bmsc=5049A452E2B2673B8F23D47D32B18D23~000000000000000000000000000000~YAAQgbYRYIhcrgeRAQAAMmUAHRje7rkSdT9arGwcI1x+NwD+Qw9B0nTiMCsy38LBOWE1cFJucqsYYxoYBzTBYo10MQcTbo7b7OJby21hrD+ya/dGsxv13C/PrFU4zPJ3Cq+O+mHPv0t6oBDlMw0LjylkMSPyveKWmdZfHM8Z7hD5JSfctKVaMgp+++QsmtjB5nqIQJi5oKnAQxjB6iQNpyUOR3RpMtS2s8agoaSOrkkRSvAj7GnePNjXyGkI9dJZmMqaYo2MJXRfyRTGv3ijDoUR5xdjBJyV/r6ecSQQMsf/KSKKLEAwu5KnvEQEkAf7ZSf592Gxs7dyVhsEr+V+5ZK3xjJvL2VTlYfAzrMPtO/lx++sSLZ+Y9nmgCyJ8f3/16rRfMRG5qKGgewF9OPzV06DilBIHnXcRWY4OoCTXI+pQsETkXuB5bW3q/rxQqQzefoISlZAFj4s8qosKSnNyg==; nsit=CDOdkMhgRlxMF12HnRzsqgdu; nseQuoteSymbols=[{"symbol":"NIFTY","identifier":"OPTIDXNIFTY08-08-2024PE24700.00","type":"equity"}]; nseappid=eyJhbGciOiJIUzI1NiIsInR5cCI6IkpXVCJ9.eyJpc3MiOiJhcGkubnNlIiwiYXVkIjoiYXBpLm5zZSIsImlhdCI6MTcyMjc2OTI0MywiZXhwIjoxNzIyNzc2NDQzfQ.GP09QlkPst8kMGIhQKHuy2jbLWH4rE5abau4fw02ID4; bm_sz=DE65FA929BC350ECAC6D8F1F1BE2F694~YAAQgbYRYBAPrweRAQAAUoAMHRiNN4lsZF8X01ldwBZDFip8daDiRKMMBc9zpyRcQcVbpLW/s/ccnoe6KwzgJ+wZJFZtOsp2bjQAmwkxgfX5JNyQYMQtEZPLbNQVhx77WBVmoE1SJRvSnRzG2+05HRvx0QtqA/8x28hWzrfW1gXr4jkPowCOUNTln1VgroAHD+tKnnAEFbdJ/V+VOW4LiCLbe8xlx1MltKQ7ECjqpC2Y89B5L80ZH4FcBHLqGBmf683SFfyK4ccr8cFl2avN4xPyMgvsQ4MnVgcHppSRQ/CXrTg8U+hWVd4E9SRn98CTe+KcQYl/nLyvZ8TnWZ7Ft8EbNYIaD0D+wqdNFM73q8KbUZXs//Ch1yDiFOpiaXLo6zdW3aBq2z8bsZJKuVLN4FJ0okcRCwXQIADEY/Vglgp2Dc+A0EbPwzTFDRN3JBp6Gp12fB/I5aAlzP+Bu51aeXGAhmhhrBlz9YdpuHi/7JD75HrllImEgPL1ZBVfwhjW7OZl/FtXp6lHrHJVISG5ymxxovB177TrosZHwlgV+9S+Sw==~4600643~3556420; _ga_87M7PJ3R97=GS1.1.1722767513.40.1.1722769246.58.0.0; RT="z=1&dm=nseindia.com&si=77caf0ce-9900-409d-89e9-ff0383678b2f&ss=lzfgbs39&sl=0&se=8c&tt=0&bcn=%2F%2F684d0d4a.akstat.io%2F&ld=f6jl&nu=o0qpsglo&cl=fkf"; _abck=CD13359D152E162C435086B82BC350CB~0~YAAQgbYRYMIXrweRAQAAXcsMHQyr/sM1p/jvGB1q2koc3cllPvpJPvmnQPtfPJg8xJyrQpNlB6qUILI+X8LUapwLpNPY7GXPPE6emBM2Kttq6DGHGj9DVBIdqugF3JmjMJdVeo87Tl6hvKfBQY6fQkaLRq3d3wlm3T7epe+oX1AVKV6BYHTuCM2JWDvYZOdnnJY81lHFF7gIhezpdFyT8OdBEWLSjMec75mxDU8ntZuEsxp2FFzqP+uwtcVx/V2mcnSIJZNFbMs3mv0qqBDxoA4pbxJhSzUsbIzPZy16P4W0q4gnbGzvnWACxmxci8PhoRISbRN5/BXVhSMUINJvxF0234Kxx1xtt7sbdFstx2unYfU8/RdcUXT8yyhZxpgR~-1~-1~-1; bm_sv=F4E946A45F732C5E357AB8FBF6520532~YAAQgbYRYMMXrweRAQAAXcsMHRgzoSKTVehEQ2gMj92XWSijJpZt/woL09BY7KFKA90mjleCMkY+H1Z/kzjIY9ZoxoqEKPvmBqwn4PPzsXDGdNt59W2Y1FbU/fDVao1V2Jo9MqAQYoQ1t4B/xD7+UbNEmeP/WM10sJffYclMaiNuHHDZwyIbZqUrUuEtSebeqYl+BfQdIKyJSkPbKMlNvaLYR0f2d2GLo9vEiMtiNJTEAkzqUyz1nWONB313CtlbeAYrNg==~1

Sheet Data Dump
B1: OI | C1: CHNG IN OI | D1: VOLUME | E1: IV | F1: LTP | G1: CHNG | H1: BID QTY | I1: BID | J1: ASK | K1: ASK QTY | L1: STRIKE | M1: BID QTY | N1: BID | O1: ASK | P1: ASK QTY | Q1: CHNG | R1: LTP | S1: IV | T1: VOLUME | U1: CHNG IN OI | V1: OI
B2: =INDEX('abcd (2)'!B:B,MATCH(L2,'abcd (2)'!L:L,0)) -> #N/A | C2: =INDEX('abcd (2)'!C:C,MATCH(L2,'abcd (2)'!L:L,0)) -> #N/A | D2: =INDEX('abcd (2)'!D:D,MATCH(L2,'abcd (2)'!L:L,0)) -> #N/A | E2: =INDEX('abcd (2)'!E:E,MATCH(L2,'abcd (2)'!L:L,0)) -> #N/A | L2: =L3-50 -> 24350 | S2: =INDEX('abcd (2)'!S:S,MATCH(L2,'abcd (2)'!L:L,0)) -> #N/A | T2: =INDEX('abcd (2)'!T:T,MATCH(L2,'abcd (2)'!L:L,0)) -> #N/A | U2: =INDEX('abcd (2)'!U:U,MATCH(L2,'abcd (2)'!L:L,0)) -> #N/A | V2: =INDEX('abcd (2)'!V:V,MATCH(L2,'abcd (2)'!L:L,0)) -> #N/A
B3: =INDEX('abcd (2)'!B:B,MATCH(L3,'abcd (2)'!L:L,0)) -> #N/A | C3: =INDEX('abcd (2)'!C:C,MATCH(L3,'abcd (2)'!L:L,0)) -> #N/A | D3: =INDEX('abcd (2)'!D:D,MATCH(L3,'abcd (2)'!L:L,0)) -> #N/A | E3: =INDEX('abcd (2)'!E:E,MATCH(L3,'abcd (2)'!L:L,0)) -> #N/A | L3: =L4-50 -> 24400 | S3: =INDEX('abcd (2)'!S:S,MATCH(L3,'abcd (2)'!L:L,0)) -> #N/A | T3: =INDEX('abcd (2)'!T:T,MATCH(L3,'abcd (2)'!L:L,0)) -> #N/A | U3: =INDEX('abcd (2)'!U:U,MATCH(L3,'abcd (2)'!L:L,0)) -> #N/A | V3: =INDEX('abcd (2)'!V:V,MATCH(L3,'abcd (2)'!L:L,0)) -> #N/A
B4: =INDEX('abcd (2)'!B:B,MATCH(L4,'abcd (2)'!L:L,0)) -> #N/A | C4: =INDEX('abcd (2)'!C:C,MATCH(L4,'abcd (2)'!L:L,0)) -> #N/A | D4: =INDEX('abcd (2)'!D:D,MATCH(L4,'abcd (2)'!L:L,0)) -> #N/A | E4: =INDEX('abcd (2)'!E:E,MATCH(L4,'abcd (2)'!L:L,0)) -> #N/A | L4: =L5-50 -> 24450 | S4: =INDEX('abcd (2)'!S:S,MATCH(L4,'abcd (2)'!L:L,0)) -> #N/A | T4: =INDEX('abcd (2)'!T:T,MATCH(L4,'abcd (2)'!L:L,0)) -> #N/A | U4: =INDEX('abcd (2)'!U:U,MATCH(L4,'abcd (2)'!L:L,0)) -> #N/A | V4: =INDEX('abcd (2)'!V:V,MATCH(L4,'abcd (2)'!L:L,0)) -> #N/A
B5: =INDEX('abcd (2)'!B:B,MATCH(L5,'abcd (2)'!L:L,0)) -> #N/A | C5: =INDEX('abcd (2)'!C:C,MATCH(L5,'abcd (2)'!L:L,0)) -> #N/A | D5: =INDEX('abcd (2)'!D:D,MATCH(L5,'abcd (2)'!L:L,0)) -> #N/A | E5: =INDEX('abcd (2)'!E:E,MATCH(L5,'abcd (2)'!L:L,0)) -> #N/A | L5: =L6-50 -> 24500 | S5: =INDEX('abcd (2)'!S:S,MATCH(L5,'abcd (2)'!L:L,0)) -> #N/A | T5: =INDEX('abcd (2)'!T:T,MATCH(L5,'abcd (2)'!L:L,0)) -> #N/A | U5: =INDEX('abcd (2)'!U:U,MATCH(L5,'abcd (2)'!L:L,0)) -> #N/A | V5: =INDEX('abcd (2)'!V:V,MATCH(L5,'abcd (2)'!L:L,0)) -> #N/A
B6: =INDEX('abcd (2)'!B:B,MATCH(L6,'abcd (2)'!L:L,0)) -> #N/A | C6: =INDEX('abcd (2)'!C:C,MATCH(L6,'abcd (2)'!L:L,0)) -> #N/A | D6: =INDEX('abcd (2)'!D:D,MATCH(L6,'abcd (2)'!L:L,0)) -> #N/A | E6: =INDEX('abcd (2)'!E:E,MATCH(L6,'abcd (2)'!L:L,0)) -> #N/A | L6: =Entry!A2 -> 24550 | S6: =INDEX('abcd (2)'!S:S,MATCH(L6,'abcd (2)'!L:L,0)) -> #N/A | T6: =INDEX('abcd (2)'!T:T,MATCH(L6,'abcd (2)'!L:L,0)) -> #N/A | U6: =INDEX('abcd (2)'!U:U,MATCH(L6,'abcd (2)'!L:L,0)) -> #N/A | V6: =INDEX('abcd (2)'!V:V,MATCH(L6,'abcd (2)'!L:L,0)) -> #N/A
B7: =INDEX('abcd (2)'!B:B,MATCH(L7,'abcd (2)'!L:L,0)) -> #N/A | C7: =INDEX('abcd (2)'!C:C,MATCH(L7,'abcd (2)'!L:L,0)) -> #N/A | D7: =INDEX('abcd (2)'!D:D,MATCH(L7,'abcd (2)'!L:L,0)) -> #N/A | E7: =INDEX('abcd (2)'!E:E,MATCH(L7,'abcd (2)'!L:L,0)) -> #N/A | L7: =L6+50 -> 24600 | S7: =INDEX('abcd (2)'!S:S,MATCH(L7,'abcd (2)'!L:L,0)) -> #N/A | T7: =INDEX('abcd (2)'!T:T,MATCH(L7,'abcd (2)'!L:L,0)) -> #N/A | U7: =INDEX('abcd (2)'!U:U,MATCH(L7,'abcd (2)'!L:L,0)) -> #N/A | V7: =INDEX('abcd (2)'!V:V,MATCH(L7,'abcd (2)'!L:L,0)) -> #N/A
B8: =INDEX('abcd (2)'!B:B,MATCH(L8,'abcd (2)'!L:L,0)) -> #N/A | C8: =INDEX('abcd (2)'!C:C,MATCH(L8,'abcd (2)'!L:L,0)) -> #N/A | D8: =INDEX('abcd (2)'!D:D,MATCH(L8,'abcd (2)'!L:L,0)) -> #N/A | E8: =INDEX('abcd (2)'!E:E,MATCH(L8,'abcd (2)'!L:L,0)) -> #N/A | L8: =L7+50 -> 24650 | S8: =INDEX('abcd (2)'!S:S,MATCH(L8,'abcd (2)'!L:L,0)) -> #N/A | T8: =INDEX('abcd (2)'!T:T,MATCH(L8,'abcd (2)'!L:L,0)) -> #N/A | U8: =INDEX('abcd (2)'!U:U,MATCH(L8,'abcd (2)'!L:L,0)) -> #N/A | V8: =INDEX('abcd (2)'!V:V,MATCH(L8,'abcd (2)'!L:L,0)) -> #N/A
B9: =INDEX('abcd (2)'!B:B,MATCH(L9,'abcd (2)'!L:L,0)) -> #N/A | C9: =INDEX('abcd (2)'!C:C,MATCH(L9,'abcd (2)'!L:L,0)) -> #N/A | D9: =INDEX('abcd (2)'!D:D,MATCH(L9,'abcd (2)'!L:L,0)) -> #N/A | E9: =INDEX('abcd (2)'!E:E,MATCH(L9,'abcd (2)'!L:L,0)) -> #N/A | L9: =L8+50 -> 24700 | S9: =INDEX('abcd (2)'!S:S,MATCH(L9,'abcd (2)'!L:L,0)) -> #N/A | T9: =INDEX('abcd (2)'!T:T,MATCH(L9,'abcd (2)'!L:L,0)) -> #N/A | U9: =INDEX('abcd (2)'!U:U,MATCH(L9,'abcd (2)'!L:L,0)) -> #N/A | V9: =INDEX('abcd (2)'!V:V,MATCH(L9,'abcd (2)'!L:L,0)) -> #N/A
B10: =INDEX('abcd (2)'!B:B,MATCH(L10,'abcd (2)'!L:L,0)) -> #N/A | C10: =INDEX('abcd (2)'!C:C,MATCH(L10,'abcd (2)'!L:L,0)) -> #N/A | D10: =INDEX('abcd (2)'!D:D,MATCH(L10,'abcd (2)'!L:L,0)) -> #N/A | E10: =INDEX('abcd (2)'!E:E,MATCH(L10,'abcd (2)'!L:L,0)) -> #N/A | L10: =L9+50 -> 24750 | S10: =INDEX('abcd (2)'!S:S,MATCH(L10,'abcd (2)'!L:L,0)) -> #N/A | T10: =INDEX('abcd (2)'!T:T,MATCH(L10,'abcd (2)'!L:L,0)) -> #N/A | U10: =INDEX('abcd (2)'!U:U,MATCH(L10,'abcd (2)'!L:L,0)) -> #N/A | V10: =INDEX('abcd (2)'!V:V,MATCH(L10,'abcd (2)'!L:L,0)) -> #N/A
B11: =INDEX('abcd (2)'!B:B,MATCH(L11,'abcd (2)'!L:L,0)) -> #N/A | C11: =INDEX('abcd (2)'!C:C,MATCH(L11,'abcd (2)'!L:L,0)) -> #N/A | D11: =INDEX('abcd (2)'!D:D,MATCH(L11,'abcd (2)'!L:L,0)) -> #N/A | E11: =INDEX('abcd (2)'!E:E,MATCH(L11,'abcd (2)'!L:L,0)) -> #N/A | L11: =L10+50 -> 24800 | S11: =INDEX('abcd (2)'!S:S,MATCH(L11,'abcd (2)'!L:L,0)) -> #N/A | T11: =INDEX('abcd (2)'!T:T,MATCH(L11,'abcd (2)'!L:L,0)) -> #N/A | U11: =INDEX('abcd (2)'!U:U,MATCH(L11,'abcd (2)'!L:L,0)) -> #N/A | V11: =INDEX('abcd (2)'!V:V,MATCH(L11,'abcd (2)'!L:L,0)) -> #N/A

Sheet abcd (2)
A1: Column1 | B1: Column2 | C1: Column3 | D1: Column4 | E1: Column5 | F1: Column6 | G1: Column7 | H1: Column8 | I1: Column9 | J1: Column10 | K1: Column11 | L1: Column12 | M1: Column13 | N1: Column14 | O1: Column15 | P1: Column16 | Q1: Column17 | R1: Column18 | S1: Column19 | T1: Column20 | U1: Column21 | V1: Column22 | W1: Column23
A2: CALLS
F3: LTP | G3: CHNG | H3: BID QTY | I3: BID | J3: ASK | K3: ASK QTY | M3: BID QTY | N3: BID | O3: ASK | P3: ASK QTY | Q3: CHNG | R3: LTP

Sheet Data
A1: S.no | B1: Variable | C1: Index | D1: OI | E1: CHNG IN OI | F1: VOLUME | G1: IV | H1: LTP | I1: CHNG | J1: BID QTY | K1: BID | L1: ASK | M1: ASK QTY | N1: STRIKE | O1: BID QTY | P1: BID | Q1: ASK | R1: ASK QTY | S1: CHNG | T1: LTP | U1: IV | V1: VOLUME | W1: CHNG IN OI | X1: OI
A2: 1 | B2: 1 | C2: =B2*N2 -> 24350 | N2: 24350
A3: 2 | B3: 1 | C3: =B3*N3 -> 24400 | N3: 24400
A4: 3 | B4: 1 | C4: =B4*N4 -> 24450 | N4: 24450
A5: 4 | B5: 1 | C5: =B5*N5 -> 24500 | N5: 24500
A6: 5 | B6: 1 | C6: =B6*N6 -> 24550 | N6: 24550
A7: 6 | B7: 1 | C7: =B7*N7 -> 24600 | N7: 24600
A8: 7 | B8: 1 | C8: =B8*N8 -> 24650 | N8: 24650
A9: 8 | B9: 1 | C9: =B9*N9 -> 24700 | N9: 24700
A10: 9 | B10: 1 | C10: =B10*N10 -> 24750 | N10: 24750
A11: 10 | B11: 1 | C11: =B11*N11 -> 24800 | N11: 24800
A12: 11 | B12: =B2+1 -> 2 | C12: =B12*N12 -> 48700 | D12: 15825 | E12: -16163 | F12: 1345543 | G12: 0 | N12: 24350 | U12: 7.12 | V12: 7462872 | W12: 89389 | X12: 121371
A13: 12 | B13: =B3+1 -> 2 | C13: =B13*N13 -> 48800 | D13: 36079 | E13: -44969 | F13: 4720580 | G13: 0 | N13: 24400 | U13: 5.86 | V13: 15002804 | W13: 187195 | X13: 231646
A14: 13 | B14: =B4+1 -> 2 | C14: =B14*N14 -> 48900 | D14: 48946 | E14: 801 | F14: 6870743 | G14: 0 | N14: 24450 | U14: 4.69 | V14: 17294893 | W14: 216164 | X14: 230107
A15: 14 | B15: =B5+1 -> 2 | C15: =B15*N15 -> 49000 | D15: 133194 | E15: 23461 | F15: 20522877 | G15: 0 | N15: 24500 | U15: 4.36 | V15: 33135484 | W15: 435641 | X15: 462259
A16: 15 | B16: =B6+1 -> 2 | C16: =B16*N16 -> 49100 | D16: 308880 | E16: 274161 | F16: 32034600 | G16: 1 | N16: 24550 | U16: 4.59 | V16: 32346079 | W16: 745195 | X16: 747707
A17: 16 | B17: =B7+1 -> 2 | C17: =B17*N17 -> 49200 | D17: 601666 | E17: 510348 | F17: 39461918 | G17: 3 | N17: 24600 | U17: 6.49 | V17: 13308130 | W17: 254875 | X17: 259097
A18: 17 | B18: =B8+1 -> 2 | C18: =B18*N18 -> 49300 | D18: 204169 | E18: 166368 | F18: 19092288 | G18: 4 | N18: 24650 | U18: 9.3 | V18: 2525480 | W18: 49897 | X18: 50775
A19: 18 | B19: =B9+1 -> 2 | C19: =B19*N19 -> 49400 | D19: 186179 | E19: 121269 | F19: 11454703 | G19: 5 | N19: 24700 | U19: 12.01 | V19: 1429013 | W19: 21668 | X19: 25535
A20: 19 | B20: =B10+1 -> 2 | C20: =B20*N20 -> 49500 | D20: 117763 | E20: 82375 | F20: 5136366 | G20: 6 | N20: 24750 | U20: 14.6 | V20: 299292 | W20: 5103 | X20: 5719
A21: 20 | B21: =B11+1 -> 2 | C21: =B21*N21 -> 49600 | D21: 194539 | E21: 87458 | F21: 4155609 | G21: 7 | N21: 24800 | U21: 16.9 | V21: 215868 | W21: 5207 | X21: 6615
A22: 21 | B22: =B12+1 -> 3 | C22: =B22*N22 -> 73050 | D22: 16367 | E22: -15621 | F22: 1340486 | G22: 0 | N22: 24350 | U22: 7.12 | V22: 7414945 | W22: 90652 | X22: 122634
A23: 22 | B23: =B13+1 -> 3 | C23: =B23*N23 -> 73200 | D23: 42008 | E23: -39040 | F23: 4696028 | G23: 0 | N23: 24400 | U23: 5.96 | V23: 14907266 | W23: 209193 | X23: 253644
... A161: 160 | B161: =B151+1 -> 16 | C161: =B161*N161 -> 396000 | D161: 137109 | E161: 101721 | F161: 4526111 | G161: 6 | N161: 24750 | U161: 14.23 | V161: 211659 | W161: 5061 | X161: 5677
D162: 29586 | E162: -21237 | F162: 1130239 | G162: 0 | N162: 24300 | U162: 9.79 | V162: 6526717 | W162: 152100 | X162: 240200
D163: 23624 | E163: -8364 | F163: 1244202 | G163: 0 | N163: 24350 | U163: 8.63 | V163: 6658688 | W163: 151562 | X163: 183544
D164: 74770 | E164: -6278 | F164: 4251683 | G164: 0 | N164: 24400 | U164: 7.92 | V164: 12811802 | W164: 395588 | X164: 440039
D165: 105908 | E165: 57763 | F165: 6047365 | G165: 0 | N165: 24450 | U165: 7.25 | V165: 13462207 | W165: 434515 | X165: 448458
D166: 348861 | E166: 239128 | F166: 16350791 | G166: 0 | N166: 24500 | U166: 7.38 | V166: 22266015 | W166: 791031 | X166: 817649
D167: 557002 | E167: 522283 | F167: 19041055 | G167: 1 | N167: 24550 | U167: 8.32 | V167: 13671438 | W167: 361541 | X167: 364053
D168: 568771 | E168: 477453 | F168: 20176872 | G168: 3 | N168: 24600 | U168: 10.59 | V168: 6568440 | W168: 165571 | X168: 169793
D169: 233545 | E169: 195744 | F169: 12944091 | G169: 4 | N169: 24650 | U169: 13.73 | V169: 1462888 | W169: 29279 | X169: 30157
D170: 235170 | E170: 170260 | F170: 9492930 | G170: 5 | N170: 24700 | U170: 16.94 | V170: 1006560 | W170: 23704 | X170: 27571
D171: 136499 | E171: 101111 | F171: 4490175 | G171: 6 | N171: 24750 | U171: 19.36 | V171: 207107 | W171: 5006 | X171: 5622

Sheet Info
A1: =Entry!$A$2-200 -> 24350 | B1: Call OI | C1: Put OI | D1: Change Call | E1: Change Put | F1: PCR | G1: Change PCR | H1: =Entry!$A$2-150 -> 24400 | I1: Call OI | J1: Put OI | K1: Change Call | L1: Change Put | M1: PCR | N1: Change PCR | O1: =Entry!$A$2-100 -> 24450 | P1: Call OI | Q1: Put OI | R1: Change Call | S1: Change Put | T1: PCR | U1: Change PCR | V1: =Entry!$A$2-50 -> 24500 | W1: Call OI | X1: Put OI | Y1: Change Call | Z1: Change Put | AA1: PCR | AB1: Change PCR | AC1: =Entry!$A$2 -> 24550 | AD1: Call OI | AE1: Put OI | AF1: Change Call | AG1: Change Put | AH1: PCR | AI1: Change PCR
A2: 1 | B2: =IF(ISNUMBER(VLOOKUP($A$1*A2,Data!$C$1:$D$81,2,FALSE)*25)=TRUE,VLOOKUP($A$1*A2,Data!$C$1:$D$81,2,FALSE)*25,0) -> 0 | C2: =IF(ISNUMBER(VLOOKUP($A$1*A2,Data!$C$1:$X$81,22,FALSE)*25)=TRUE,VLOOKUP($A$1*A2,Data!$C$1:$X$81,22,FALSE)*25,0) -> 0 | D2: =IF(ISNUMBER(VLOOKUP($A$1*A2,Data!$C$1:$X$81,3,FALSE)*25)=TRUE,VLOOKUP($A$1*A2,Data!$C$1:$X$81,3,FALSE)*25,0) -> 0 | E2: =IF(ISNUMBER(VLOOKUP($A$1*A2,Data!$C$1:$X$81,21,FALSE)*25)=TRUE,VLOOKUP($A$1*A2,Data!$C$1:$X$81,21,FALSE)*25,0) -> 0 | F2: =C2/B2 -> #DIV/0! | G2: =IF(E2<0, IF(D2<0,D2/E2,-10),IF(D2<0,10,E2/D2)) -> #DIV/0! | H2: 1 | I2: =IF(ISNUMBER(VLOOKUP($H$1*H2,Data!$C$1:$D$81,2,FALSE)*25)=TRUE,VLOOKUP($H$1*H2,Data!$C$1:$D$81,2,FALSE)*25,0) -> 0 | J2: =IF(ISNUMBER(VLOOKUP($H$1*H2,Data!$C$1:$X$81,22,FALSE)*25)=TRUE,VLOOKUP($H$1*H2,Data!$C$1:$X$81,22,FALSE)*25,0) -> 0 | K2: =IF(ISNUMBER(VLOOKUP($H$1*H2,Data!$C$1:$X$81,3,FALSE)*25)=TRUE,VLOOKUP($H$1*H2,Data!$C$1:$X$81,3,FALSE)*25,0) -> 0 | L2: =IF(ISNUMBER(VLOOKUP($H$1*H2,Data!$C$1:$X$81,21,FALSE)*25)=TRUE,VLOOKUP($H$1*H2,Data!$C$1:$X$81,21,FALSE)*25,0) -> 0 | M2: =J2/I2 -> #DIV/0! | N2: =IF(L2<0, IF(K2<0,K2/L2,-10),IF(K2<0,10,L2/K2)) -> #DIV/0! | O2: 1 | P2: =IF(ISNUMBER(VLOOKUP($O$1*O2,Data!$C$1:$D$81,2,FALSE)*25)=TRUE,VLOOKUP($O$1*O2,Data!$C$1:$D$81,2,FALSE)*25,0) -> 0 | Q2: =IF(ISNUMBER(VLOOKUP($O$1*O2,Data!$C$1:$X$81,22,FALSE)*25)=TRUE,VLOOKUP($O$1*O2,Data!$C$1:$X$81,22,FALSE)*25,0) -> 0 | R2: =IF(ISNUMBER(VLOOKUP($O$1*O2,Data!$C$1:$X$81,3,FALSE)*25)=TRUE,VLOOKUP($O$1*O2,Data!$C$1:$X$81,3,FALSE)*25,0) -> 0 | S2: =IF(ISNUMBER(VLOOKUP($O$1*O2,Data!$C$1:$X$81,21,FALSE)*25)=TRUE,VLOOKUP($O$1*O2,Data!$C$1:$X$81,21,FALSE)*25,0) -> 0 | T2: =Q2/P2 -> #DIV/0! | U2: =IF(S2<0, IF(R2<0,R2/S2,-10),IF(R2<0,10,S2/R2)) -> #DIV/0! | V2: 1 | W2: =IF(ISNUMBER(VLOOKUP($V$1*V2,Data!$C$1:$D$81,2,FALSE)*25)=TRUE,VLOOKUP($V$1*V2,Data!$C$1:$D$81,2,FALSE)*25,0) -> 0 | X2: =IF(ISNUMBER(VLOOKUP($V$1*V2,Data!$C$1:$X$81,22,FALSE)*25)=TRUE,VLOOKUP($V$1*V2,Data!$C$1:$X$81,22,FALSE)*25,0) -> 0 | Y2: =IF(ISNUMBER(VLOOKUP($V$1*V2,Data!$C$1:$X$81,3,FALSE)*25)=TRUE,VLOOKUP($V$1*V2,Data!$C$1:$X$81,3,FALSE)*25,0) -> 0 | Z2: =IF(ISNUMBER(VLOOKUP($V$1*V2,Data!$C$1:$X$81,21,FALSE)*25)=TRUE,VLOOKUP($V$1*V2,Data!$C$1:$X$81,21,FALSE)*25,0) -> 0 | AA2: =X2/W2 -> #DIV/0! | AB2: =IF(Z2<0, IF(Y2<0,Y2/Z2,-10),IF(Y2<0,10,Z2/Y2)) -> #DIV/0! | AC2: 1 | AD2: =IF(ISNUMBER(VLOOKUP($AC$1*AC2,Data!$C$1:$D$161,2,FALSE)*25)=TRUE,VLOOKUP($AC$1*AC2,Data!$C$1:$D$161,2,FALSE)*25,0) -> 0 | AE2: =IF(ISNUMBER(VLOOKUP($AC$1*AC2,Data!$C$1:$X$161,22,FALSE)*25)=TRUE,VLOOKUP($AC$1*AC2,Data!$C$1:$X$161,22,FALSE)*25,0) -> 0 | AF2: =IF(ISNUMBER(VLOOKUP($AC$1*AC2,Data!$C$1:$X$161,3,FALSE)*25)=TRUE,VLOOKUP($AC$1*AC2,Data!$C$1:$X$161,3,FALSE)*25,0) -> 0 | AG2: =IF(ISNUMBER(VLOOKUP($AC$1*AC2,Data!$C$1:$X$161,21,FALSE)*25)=TRUE,VLOOKUP($AC$1*AC2,Data!$C$1:$X$161,21,FALSE)*25,0) -> 0 | AH2: =AE2/AD2 -> #DIV/0! | AI2: =IF(AG2<0, IF(AF2<0,AF2/AG2,-10),IF(AF2<0,10,AG2/AF2)) -> #DIV/0!
A3: 2 | B3: =IF(ISNUMBER(VLOOKUP($A$1*A3,Data!$C$1:$D$81,2,FALSE)*25)=TRUE,VLOOKUP($A$1*A3,Data!$C$1:$D$81,2,FALSE)*25,0) -> 395625 | C3: =IF(ISNUMBER(VLOOKUP($A$1*A3,Data!$C$1:$X$81,22,FALSE)*25)=TRUE,VLOOKUP($A$1*A3,Data!$C$1:$X$81,22,FALSE)*25,0) -> 3034275 | D3: =IF(ISNUMBER(VLOOKUP($A$1*A3,Data!$C$1:$X$81,3,FALSE)*25)=TRUE,VLOOKUP($A$1*A3,Data!$C$1:$X$81,3,FALSE)*25,0) -> -404075 | E3: =IF(ISNUMBER(VLOOKUP($A$1*A3,Data!$C$1:$X$81,21,FALSE)*25)=TRUE,VLOOKUP($A$1*A3,Data!$C$1:$X$81,21,FALSE)*25,0) -> 2234725 | F3: =C3/B3 -> 7.6695735 | G3: =IF(E3<0, IF(D3<0,D3/E3,-10),IF(D3<0,10,E3/D3)) -> 10 | H3: 2 | I3: =IF(ISNUMBER(VLOOKUP($H$1*H3,Data!$C$1:$D$81,2,FALSE)*25)=TRUE,VLOOKUP($H$1*H3,Data!$C$1:$D$81,2,FALSE)*25,0) -> 901975 | J3: =IF(ISNUMBER(VLOOKUP($H$1*H3,Data!$C$1:$X$81,22,FALSE)*25)=TRUE,VLOOKUP($H$1*H3,Data!$C$1:$X$81,22,FALSE)*25,0) -> 5791150 | K3: =IF(ISNUMBER(VLOOKUP($H$1*H3,Data!$C$1:$X$81,3,FALSE)*25)=TRUE,VLOOKUP($H$1*H3,Data!$C$1:$X$81,3,FALSE)*25,0) -> -1124225 | L3: =IF(ISNUMBER(VLOOKUP($H$1*H3,Data!$C$1:$X$81,21,FALSE)*25)=TRUE,VLOOKUP($H$1*H3,Data!$C$1:$X$81,21,FALSE)*25,0) -> 4679875 | M3: =J3/I3 -> 6.4205216 | N3: =IF(L3<0, IF(K3<0,K3/L3,-10),IF(K3<0,10,L3/K3)) -> 10 | O3: 2 | P3: =IF(ISNUMBER(VLOOKUP($O$1*O3,Data!$C$1:$D$81,2,FALSE)*25)=TRUE,VLOOKUP($O$1*O3,Data!$C$1:$D$81,2,FALSE)*25,0) -> 1223650 | Q3: =IF(ISNUMBER(VLOOKUP($O$1*O3,Data!$C$1:$X$81,22,FALSE)*25)=TRUE,VLOOKUP($O$1*O3,Data!$C$1:$X$81,22,FALSE)*25,0) -> 5752675 | R3: =IF(ISNUMBER(VLOOKUP($O$1*O3,Data!$C$1:$X$81,3,FALSE)*25)=TRUE,VLOOKUP($O$1*O3,Data!$C$1:$X$81,3,FALSE)*25,0) -> 20025 | S3: =IF(ISNUMBER(VLOOKUP($O$1*O3,Data!$C$1:$X$81,21,FALSE)*25)=TRUE,VLOOKUP($O$1*O3,Data!$C$1:$X$81,21,FALSE)*25,0) -> 5404100 | T3: =Q3/P3 -> 4.7012422 | U3: =IF(S3<0, IF(R3<0,R3/S3,-10),IF(R3<0,10,S3/R3)) -> 269.86767 | V3: 2 | W3: =IF(ISNUMBER(VLOOKUP($V$1*V3,Data!$C$1:$D$81,2,FALSE)*25)=TRUE,VLOOKUP($V$1*V3,Data!$C$1:$D$81,2,FALSE)*25,0) -> 3329850 | X3: =IF(ISNUMBER(VLOOKUP($V$1*V3,Data!$C$1:$X$81,22,FALSE)*25)=TRUE,VLOOKUP($V$1*V3,Data!$C$1:$X$81,22,FALSE)*25,0) -> 11556475 | Y3: =IF(ISNUMBER(VLOOKUP($V$1*V3,Data!$C$1:$X$81,3,FALSE)*25)=TRUE,VLOOKUP($V$1*V3,Data!$C$1:$X$81,3,FALSE)*25,0) -> 586525 | Z3: =IF(ISNUMBER(VLOOKUP($V$1*V3,Data!$C$1:$X$81,21,FALSE)*25)=TRUE,VLOOKUP($V$1*V3,Data!$C$1:$X$81,21,FALSE)*25,0) -> 10891025 | AA3: =X3/W3 -> 3.4705692 | AB3: =IF(Z3<0, IF(Y3<0,Y3/Z3,-10),IF(Y3<0,10,Z3/Y3)) -> 18.568731 | AC3: 2 | AD3: =IF(ISNUMBER(VLOOKUP($AC$1*AC3,Data!$C$1:$D$161,2,FALSE)*25)=TRUE,VLOOKUP($AC$1*AC3,Data!$C$1:$D$161,2,FALSE)*25,0) -> 7722000 | AE3: =IF(ISNUMBER(VLOOKUP($AC$1*AC3,Data!$C$1:$X$161,22,FALSE)*25)=TRUE,VLOOKUP($AC$1*AC3,Data!$C$1:$X$161,22,FALSE)*25,0) -> 18692675 | AF3: =IF(ISNUMBER(VLOOKUP($AC$1*AC3,Data!$C$1:$X$161,3,FALSE)*25)=TRUE,VLOOKUP($AC$1*AC3,Data!$C$1:$X$161,3,FALSE)*25,0) -> 6854025 | AG3: =IF(ISNUMBER(VLOOKUP($AC$1*AC3,Data!$C$1:$X$161,21,FALSE)*25)=TRUE,VLOOKUP($AC$1*AC3,Data!$C$1:$X$161,21,FALSE)*25,0) -> 18629875 | AH3: =AE3/AD3 -> 2.4207038 | AI3: =IF(AG3<0, IF(AF3<0,AF3/AG3,-10),IF(AF3<0,10,AG3/AF3)) -> 2.7180927
A4: 3 | B4: =IF(ISNUMBER(VLOOKUP($A$1*A4,Data!$C$1:$D$81,2,FALSE)*25)=TRUE,VLOOKUP($A$1*A4,Data!$C$1:$D$81,2,FALSE)*25,0) -> 409175 | C4: =IF(ISNUMBER(VLOOKUP($A$1*A4,Data!$C$1:$X$81,22,FALSE)*25)=TRUE,VLOOKUP($A$1*A4,Data!$C$1:$X$81,22,FALSE)*25,0) -> 3065850 | D4: =IF(ISNUMBER(VLOOKUP($A$1*A4,Data!$C$1:$X$81,3,FALSE)*25)=TRUE,VLOOKUP($A$1*A4,Data!$C$1:$X$81,3,FALSE)*25,0) -> -390525 | E4: =IF(ISNUMBER(VLOOKUP($A$1*A4,Data!$C$1:$X$81,21,FALSE)*25)=TRUE,VLOOKUP($A$1*A4,Data!$C$1:$X$81,21,FALSE)*25,0) -> 2266300 | F4: =C4/B4 -> 7.4927598 | G4: =IF(E4<0, IF(D4<0,D4/E4,-10),IF(D4<0,10,E4/D4)) -> 10 | H4: 3 | I4: =IF(ISNUMBER(VLOOKUP($H$1*H4,Data!$C$1:$D$81,2,FALSE)*25)=TRUE,VLOOKUP($H$1*H4,Data!$C$1:$D$81,2,FALSE)*25,0) -> 1050200 | J4: =IF(ISNUMBER(VLOOKUP($H$1*H4,Data!$C$1:$X$81,22,FALSE)*25)=TRUE,VLOOKUP($H$1*H4,Data!$C$1:$X$81,22,FALSE)*25,0) -> 6341100 | K4: =IF(ISNUMBER(VLOOKUP($H$1*H4,Data!$C$1:$X$81,3,FALSE)*25)=TRUE,VLOOKUP($H$1*H4,Data!$C$1:$X$81,3,FALSE)*25,0) -> -976000 | L4: =IF(ISNUMBER(VLOOKUP($H$1*H4,Data!$C$1:$X$81,21,FALSE)*25)=TRUE,VLOOKUP($H$1*H4,Data!$C$1:$X$81,21,FALSE)*25,0) -> 5229825 | M4: =J4/I4 -> 6.0379928 | N4: =IF(L4<0, IF(K4<0,K4/L4,-10),IF(K4<0,10,L4/K4)) -> 10 | O4: 3 | P4: =IF(ISNUMBER(VLOOKUP($O$1*O4,Data!$C$1:$D$81,2,FALSE)*25)=TRUE,VLOOKUP($O$1*O4,Data!$C$1:$D$81,2,FALSE)*25,0) -> 1406325 | Q4: =IF(ISNUMBER(VLOOKUP($O$1*O4,Data!$C$1:$X$81,22,FALSE)*25)=TRUE,VLOOKUP($O$1*O4,Data!$C$1:$X$81,22,FALSE)*25,0) -> 6036475 | R4: =IF(ISNUMBER(VLOOKUP($O$1*O4,Data!$C$1:$X$81,3,FALSE)*25)=TRUE,VLOOKUP($O$1*O4,Data!$C$1:$X$81,3,FALSE)*25,0) -> 202700 | S4: =IF(ISNUMBER(VLOOKUP($O$1*O4,Data!$C$1:$X$81,21,FALSE)*25)=TRUE,VLOOKUP($O$1*O4,Data!$C$1:$X$81,21,FALSE)*25,0) -> 5687900 | T4: =Q4/P4 -> 4.2923755 | U4: =IF(S4<0, IF(R4<0,R4/S4,-10),IF(R4<0,10,S4/R4)) -> 28.060681 | V4: 3 | W4: =IF(ISNUMBER(VLOOKUP($V$1*V4,Data!$C$1:$D$81,2,FALSE)*25)=TRUE,VLOOKUP($V$1*V4,Data!$C$1:$D$81,2,FALSE)*25,0) -> 3770000 | X4: =IF(ISNUMBER(VLOOKUP($V$1*V4,Data!$C$1:$X$81,22,FALSE)*25)=TRUE,VLOOKUP($V$1*V4,Data!$C$1:$X$81,22,FALSE)*25,0) -> 13124125 | Y4: =IF(ISNUMBER(VLOOKUP($V$1*V4,Data!$C$1:$X$81,3,FALSE)*25)=TRUE,VLOOKUP($V$1*V4,Data!$C$1:$X$81,3,FALSE)*25,0) -> 1026675 | Z4: =IF(ISNUMBER(VLOOKUP($V$1*V4,Data!$C$1:$X$81,21,FALSE)*25)=TRUE,VLOOKUP($V$1*V4,Data!$C$1:$X$81,21,FALSE)*25,0) -> 12458675 | AA4: =X4/W4 -> 3.4812003 | AB4: =IF(Z4<0, IF(Y4<0,Y4/Z4,-10),IF(Y4<0,10,Z4/Y4)) -> 12.134975 | AC4: 3 | AD4: =IF(ISNUMBER(VLOOKUP($AC$1*AC4,Data!$C$1:$D$161,2,FALSE)*25)=TRUE,VLOOKUP($AC$1*AC4,Data!$C$1:$D$161,2,FALSE)*25,0) -> 8961725 | AE4: =IF(ISNUMBER(VLOOKUP($AC$1*AC4,Data!$C$1:$X$161,22,FALSE)*25)=TRUE,VLOOKUP($AC$1*AC4,Data!$C$1:$X$161,22,FALSE)*25,0) -> 18724275 | AF4: =IF(ISNUMBER(VLOOKUP($AC$1*AC4,Data!$C$1:$X$161,3,FALSE)*25)=TRUE,VLOOKUP($AC$1*AC4,Data!$C$1:$X$161,3,FALSE)*25,0) -> 8093750 | AG4: =IF(ISNUMBER(VLOOKUP($AC$1*AC4,Data!$C$1:$X$161,21,FALSE)*25)=TRUE,VLOOKUP($AC$1*AC4,Data!$C$1:$X$161,21,FALSE)*25,0) -> 18661475 | AH4: =AE4/AD4 -> 2.0893606 | AI4: =IF(AG4<0, IF(AF4<0,AF4/AG4,-10),IF(AF4<0,10,AG4/AF4)) -> 2.3056649
A5: 4 | B5: =IF(ISNUMBER(VLOOKUP($A$1*A5,Data!$C$1:$D$81,2,FALSE)*25)=TRUE,VLOOKUP($A$1*A5,Data!$C$1:$D$81,2,FALSE)*25,0) -> 409175 | C5: =IF(ISNUMBER(VLOOKUP($A$1*A5,Data!$C$1:$X$81,22,FALSE)*25)=TRUE,VLOOKUP($A$1*A5,Data!$C$1:$X$81,22,FALSE)*25,0) -> 3065850 | D5: =IF(ISNUMBER(VLOOKUP($A$1*A5,Data!$C$1:$X$81,3,FALSE)*25)=TRUE,VLOOKUP($A$1*A5,Data!$C$1:$X$81,3,FALSE)*25,0) -> -390525 | E5: =IF(ISNUMBER(VLOOKUP($A$1*A5,Data!$C$1:$X$81,21,FALSE)*25)=TRUE,VLOOKUP($A$1*A5,Data!$C$1:$X$81,21,FALSE)*25,0) -> 2266300 | F5: =C5/B5 -> 7.4927598 | G5: =IF(E5<0, IF(D5<0,D5/E5,-10),IF(D5<0,10,E5/D5)) -> 10 | H5: 4 | I5: =IF(ISNUMBER(VLOOKUP($H$1*H5,Data!$C$1:$D$81,2,FALSE)*25)=TRUE,VLOOKUP($H$1*H5,Data!$C$1:$D$81,2,FALSE)*25,0) -> 1050200 | J5: =IF(ISNUMBER(VLOOKUP($H$1*H5,Data!$C$1:$X$81,22,FALSE)*25)=TRUE,VLOOKUP($H$1*H5,Data!$C$1:$X$81,22,FALSE)*25,0) -> 6341100 | K5: =IF(ISNUMBER(VLOOKUP($H$1*H5,Data!$C$1:$X$81,3,FALSE)*25)=TRUE,VLOOKUP($H$1*H5,Data!$C$1:$X$81,3,FALSE)*25,0) -> -976000 | L5: =IF(ISNUMBER(VLOOKUP($H$1*H5,Data!$C$1:$X$81,21,FALSE)*25)=TRUE,VLOOKUP($H$1*H5,Data!$C$1:$X$81,21,FALSE)*25,0) -> 5229825 | M5: =J5/I5 -> 6.0379928 | N5: =IF(L5<0, IF(K5<0,K5/L5,-10),IF(K5<0,10,L5/K5)) -> 10 | O5: 4 | P5: =IF(ISNUMBER(VLOOKUP($O$1*O5,Data!$C$1:$D$81,2,FALSE)*25)=TRUE,VLOOKUP($O$1*O5,Data!$C$1:$D$81,2,FALSE)*25,0) -> 1406325 | Q5: =IF(ISNUMBER(VLOOKUP($O$1*O5,Data!$C$1:$X$81,22,FALSE)*25)=TRUE,VLOOKUP($O$1*O5,Data!$C$1:$X$81,22,FALSE)*25,0) -> 6036475 | R5: =IF(ISNUMBER(VLOOKUP($O$1*O5,Data!$C$1:$X$81,3,FALSE)*25)=TRUE,VLOOKUP($O$1*O5,Data!$C$1:$X$81,3,FALSE)*25,0) -> 202700 | S5: =IF(ISNUMBER(VLOOKUP($O$1*O5,Data!$C$1:$X$81,21,FALSE)*25)=TRUE,VLOOKUP($O$1*O5,Data!$C$1:$X$81,21,FALSE)*25,0) -> 5687900 | T5: =Q5/P5 -> 4.2923755 | U5: =IF(S5<0, IF(R5<0,R5/S5,-10),IF(R5<0,10,S5/R5)) -> 28.060681 | V5: 4 | W5: =IF(ISNUMBER(VLOOKUP($V$1*V5,Data!$C$1:$D$81,2,FALSE)*25)=TRUE,VLOOKUP($V$1*V5,Data!$C$1:$D$81,2,FALSE)*25,0) -> 3770000 | X5: =IF(ISNUMBER(VLOOKUP($V$1*V5,Data!$C$1:$X$81,22,FALSE)*25)=TRUE,VLOOKUP($V$1*V5,Data!$C$1:$X$81,22,FALSE)*25,0) -> 13124125 | Y5: =IF(ISNUMBER(VLOOKUP($V$1*V5,Data!$C$1:$X$81,3,FALSE)*25)=TRUE,VLOOKUP($V$1*V5,Data!$C$1:$X$81,3,FALSE)*25,0) -> 1026675 | Z5: =IF(ISNUMBER(VLOOKUP($V$1*V5,Data!$C$1:$X$81,21,FALSE)*25)=TRUE,VLOOKUP($V$1*V5,Data!$C$1:$X$81,21,FALSE)*25,0) -> 12458675 | AA5: =X5/W5 -> 3.4812003 | AB5: =IF(Z5<0, IF(Y5<0,Y5/Z5,-10),IF(Y5<0,10,Z5/Y5)) -> 12.134975 | AC5: 4 | AD5: =IF(ISNUMBER(VLOOKUP($AC$1*AC5,Data!$C$1:$D$161,2,FALSE)*25)=TRUE,VLOOKUP($AC$1*AC5,Data!$C$1:$D$161,2,FALSE)*25,0) -> 8961725 | AE5: =IF(ISNUMBER(VLOOKUP($AC$1*AC5,Data!$C$1:$X$161,22,FALSE)*25)=TRUE,VLOOKUP($AC$1*AC5,Data!$C$1:$X$161,22,FALSE)*25,0) -> 18724275 | AF5: =IF(ISNUMBER(VLOOKUP($AC$1*AC5,Data!$C$1:$X$161,3,FALSE)*25)=TRUE,VLOOKUP($AC$1*AC5,Data!$C$1:$X$161,3,FALSE)*25,0) -> 8093750 | AG5: =IF(ISNUMBER(VLOOKUP($AC$1*AC5,Data!$C$1:$X$161,21,FALSE)*25)=TRUE,VLOOKUP($AC$1*AC5,Data!$C$1:$X$161,21,FALSE)*25,0) -> 18661475 | AH5: =AE5/AD5 -> 2.0893606 | AI5: =IF(AG5<0, IF(AF5<0,AF5/AG5,-10),IF(AF5<0,10,AG5/AF5)) -> 2.3056649
A6: 5 | B6: =IF(ISNUMBER(VLOOKUP($A$1*A6,Data!$C$1:$D$81,2,FALSE)*25)=TRUE,VLOOKUP($A$1*A6,Data!$C$1:$D$81,2,FALSE)*25,0) -> 442650 | C6: =IF(ISNUMBER(VLOOKUP($A$1*A6,Data!$C$1:$X$81,22,FALSE)*25)=TRUE,VLOOKUP($A$1*A6,Data!$C$1:$X$81,22,FALSE)*25,0) -> 3552600 | D6: =IF(ISNUMBER(VLOOKUP($A$1*A6,Data!$C$1:$X$81,3,FALSE)*25)=TRUE,VLOOKUP($A$1*A6,Data!$C$1:$X$81,3,FALSE)*25,0) -> -357050 | E6: =IF(ISNUMBER(VLOOKUP($A$1*A6,Data!$C$1:$X$81,21,FALSE)*25)=TRUE,VLOOKUP($A$1*A6,Data!$C$1:$X$81,21,FALSE)*25,0) -> 2753050 | F6: =C6/B6 -> 8.025754 | G6: =IF(E6<0, IF(D6<0,D6/E6,-10),IF(D6<0,10,E6/D6)) -> 10 | H6: 5 | I6: =IF(ISNUMBER(VLOOKUP($H$1*H6,Data!$C$1:$D$81,2,FALSE)*25)=TRUE,VLOOKUP($H$1*H6,Data!$C$1:$D$81,2,FALSE)*25,0) -> 1240225 | J6: =IF(ISNUMBER(VLOOKUP($H$1*H6,Data!$C$1:$X$81,22,FALSE)*25)=TRUE,VLOOKUP($H$1*H6,Data!$C$1:$X$81,22,FALSE)*25,0) -> 7047200 | K6: =IF(ISNUMBER(VLOOKUP($H$1*H6,Data!$C$1:$X$81,3,FALSE)*25)=TRUE,VLOOKUP($H$1*H6,Data!$C$1:$X$81,3,FALSE)*25,0) -> -785975 | L6: =IF(ISNUMBER(VLOOKUP($H$1*H6,Data!$C$1:$X$81,21,FALSE)*25)=TRUE,VLOOKUP($H$1*H6,Data!$C$1:$X$81,21,FALSE)*25,0) -> 5935925 | M6: =J6/I6 -> 5.6821948 | N6: =IF(L6<0, IF(K6<0,K6/L6,-10),IF(K6<0,10,L6/K6)) -> 10 | O6: 5 | P6: =IF(ISNUMBER(VLOOKUP($O$1*O6,Data!$C$1:$D$81,2,FALSE)*25)=TRUE,VLOOKUP($O$1*O6,Data!$C$1:$D$81,2,FALSE)*25,0) -> 1615425 | Q6: =IF(ISNUMBER(VLOOKUP($O$1*O6,Data!$C$1:$X$81,22,FALSE)*25)=TRUE,VLOOKUP($O$1*O6,Data!$C$1:$X$81,22,FALSE)*25,0) -> 7074200 | R6: =IF(ISNUMBER(VLOOKUP($O$1*O6,Data!$C$1:$X$81,3,FALSE)*25)=TRUE,VLOOKUP($O$1*O6,Data!$C$1:$X$81,3,FALSE)*25,0) -> 411800 | S6: =IF(ISNUMBER(VLOOKUP($O$1*O6,Data!$C$1:$X$81,21,FALSE)*25)=TRUE,VLOOKUP($O$1*O6,Data!$C$1:$X$81,21,FALSE)*25,0) -> 6725625 | T6: =Q6/P6 -> 4.3791572 | U6: =IF(S6<0, IF(R6<0,R6/S6,-10),IF(R6<0,10,S6/R6)) -> 16.332261 | V6: 5 | W6: =IF(ISNUMBER(VLOOKUP($V$1*V6,Data!$C$1:$D$81,2,FALSE)*25)=TRUE,VLOOKUP($V$1*V6,Data!$C$1:$D$81,2,FALSE)*25,0) -> 5417725 | X6: =IF(ISNUMBER(VLOOKUP($V$1*V6,Data!$C$1:$X$81,22,FALSE)*25)=TRUE,VLOOKUP($V$1*V6,Data!$C$1:$X$81,22,FALSE)*25,0) -> 16693325 | Y6: =IF(ISNUMBER(VLOOKUP($V$1*V6,Data!$C$1:$X$81,3,FALSE)*25)=TRUE,VLOOKUP($V$1*V6,Data!$C$1:$X$81,3,FALSE)*25,0) -> 2674400 | Z6: =IF(ISNUMBER(VLOOKUP($V$1*V6,Data!$C$1:$X$81,21,FALSE)*25)=TRUE,VLOOKUP($V$1*V6,Data!$C$1:$X$81,21,FALSE)*25,0) -> 16027875 | AA6: =X6/W6 -> 3.0812426 | AB6: =IF(Z6<0, IF(Y6<0,Y6/Z6,-10),IF(Y6<0,10,Z6/Y6)) -> 5.9930732 | AC6: 5 | AD6: =IF(ISNUMBER(VLOOKUP($AC$1*AC6,Data!$C$1:$D$161,2,FALSE)*25)=TRUE,VLOOKUP($AC$1*AC6,Data!$C$1:$D$161,2,FALSE)*25,0) -> 11160300 | AE6: =IF(ISNUMBER(VLOOKUP($AC$1*AC6,Data!$C$1:$X$161,22,FALSE)*25)=TRUE,VLOOKUP($AC$1*AC6,Data!$C$1:$X$161,22,FALSE)*25,0) -> 15696650 | AF6: =IF(ISNUMBER(VLOOKUP($AC$1*AC6,Data!$C$1:$X$161,3,FALSE)*25)=TRUE,VLOOKUP($AC$1*AC6,Data!$C$1:$X$161,3,FALSE)*25,0) -> 10292325 | AG6: =IF(ISNUMBER(VLOOKUP($AC$1*AC6,Data!$C$1:$X$161,21,FALSE)*25)=TRUE,VLOOKUP($AC$1*AC6,Data!$C$1:$X$161,21,FALSE)*25,0) -> 15633850 | AH6: =AE6/AD6 -> 1.406472 | AI6: =IF(AG6<0, IF(AF6<0,AF6/AG6,-10),IF(AF6<0,10,AG6/AF6)) -> 1.5189814
A7: 6 | B7: =IF(ISNUMBER(VLOOKUP($A$1*A7,Data!$C$1:$D$81,2,FALSE)*25)=TRUE,VLOOKUP($A$1*A7,Data!$C$1:$D$81,2,FALSE)*25,0) -> 444750 | C7: =IF(ISNUMBER(VLOOKUP($A$1*A7,Data!$C$1:$X$81,22,FALSE)*25)=TRUE,VLOOKUP($A$1*A7,Data!$C$1:$X$81,22,FALSE)*25,0) -> 3869425 | D7: =IF(ISNUMBER(VLOOKUP($A$1*A7,Data!$C$1:$X$81,3,FALSE)*25)=TRUE,VLOOKUP($A$1*A7,Data!$C$1:$X$81,3,FALSE)*25,0) -> -354950 | E7: =IF(ISNUMBER(VLOOKUP($A$1*A7,Data!$C$1:$X$81,21,FALSE)*25)=TRUE,VLOOKUP($A$1*A7,Data!$C$1:$X$81,21,FALSE)*25,0) -> 3069875 | F7: =C7/B7 -> 8.7002248 | G7: =IF(E7<0, IF(D7<0,D7/E7,-10),IF(D7<0,10,E7/D7)) -> 10 | H7: 6 | I7: =IF(ISNUMBER(VLOOKUP($H$1*H7,Data!$C$1:$D$81,2,FALSE)*25)=TRUE,VLOOKUP($H$1*H7,Data!$C$1:$D$81,2,FALSE)*25,0) -> 1326700 | J7: =IF(ISNUMBER(VLOOKUP($H$1*H7,Data!$C$1:$X$81,22,FALSE)*25)=TRUE,VLOOKUP($H$1*H7,Data!$C$1:$X$81,22,FALSE)*25,0) -> 7344775 | K7: =IF(ISNUMBER(VLOOKUP($H$1*H7,Data!$C$1:$X$81,3,FALSE)*25)=TRUE,VLOOKUP($H$1*H7,Data!$C$1:$X$81,3,FALSE)*25,0) -> -699500 | L7: =IF(ISNUMBER(VLOOKUP($H$1*H7,Data!$C$1:$X$81,21,FALSE)*25)=TRUE,VLOOKUP($H$1*H7,Data!$C$1:$X$81,21,FALSE)*25,0) -> 6233500 | M7: =J7/I7 -> 5.5361235 | N7: =IF(L7<0, IF(K7<0,K7/L7,-10),IF(K7<0,10,L7/K7)) -> 10 | O7: 6 | P7: =IF(ISNUMBER(VLOOKUP($O$1*O7,Data!$C$1:$D$81,2,FALSE)*25)=TRUE,VLOOKUP($O$1*O7,Data!$C$1:$D$81,2,FALSE)*25,0) -> 1716650 | Q7: =IF(ISNUMBER(VLOOKUP($O$1*O7,Data!$C$1:$X$81,22,FALSE)*25)=TRUE,VLOOKUP($O$1*O7,Data!$C$1:$X$81,22,FALSE)*25,0) -> 7201375 | R7: =IF(ISNUMBER(VLOOKUP($O$1*O7,Data!$C$1:$X$81,3,FALSE)*25)=TRUE,VLOOKUP($O$1*O7,Data!$C$1:$X$81,3,FALSE)*25,0) -> 513025 | S7: =IF(ISNUMBER(VLOOKUP($O$1*O7,Data!$C$1:$X$81,21,FALSE)*25)=TRUE,VLOOKUP($O$1*O7,Data!$C$1:$X$81,21,FALSE)*25,0) -> 6852800 | T7: =Q7/P7 -> 4.1950165 | U7: =IF(S7<0, IF(R7<0,R7/S7,-10),IF(R7<0,10,S7/R7)) -> 13.357634 | V7: 6 | W7: =IF(ISNUMBER(VLOOKUP($V$1*V7,Data!$C$1:$D$81,2,FALSE)*25)=TRUE,VLOOKUP($V$1*V7,Data!$C$1:$D$81,2,FALSE)*25,0) -> 6049075 | X7: =IF(ISNUMBER(VLOOKUP($V$1*V7,Data!$C$1:$X$81,22,FALSE)*25)=TRUE,VLOOKUP($V$1*V7,Data!$C$1:$X$81,22,FALSE)*25,0) -> 17636625 | Y7: =IF(ISNUMBER(VLOOKUP($V$1*V7,Data!$C$1:$X$81,3,FALSE)*25)=TRUE,VLOOKUP($V$1*V7,Data!$C$1:$X$81,3,FALSE)*25,0) -> 3305750 | Z7: =IF(ISNUMBER(VLOOKUP($V$1*V7,Data!$C$1:$X$81,21,FALSE)*25)=TRUE,VLOOKUP($V$1*V7,Data!$C$1:$X$81,21,FALSE)*25,0) -> 16971175 | AA7: =X7/W7 -> 2.9155904 | AB7: =IF(Z7<0, IF(Y7<0,Y7/Z7,-10),IF(Y7<0,10,Z7/Y7)) -> 5.133835 | AC7: 6 | AD7: =IF(ISNUMBER(VLOOKUP($AC$1*AC7,Data!$C$1:$D$161,2,FALSE)*25)=TRUE,VLOOKUP($AC$1*AC7,Data!$C$1:$D$161,2,FALSE)*25,0) -> 11883000 | AE7: =IF(ISNUMBER(VLOOKUP($AC$1*AC7,Data!$C$1:$X$161,22,FALSE)*25)=TRUE,VLOOKUP($AC$1*AC7,Data!$C$1:$X$161,22,FALSE)*25,0) -> 14172625 | AF7: =IF(ISNUMBER(VLOOKUP($AC$1*AC7,Data!$C$1:$X$161,3,FALSE)*25)=TRUE,VLOOKUP($AC$1*AC7,Data!$C$1:$X$161,3,FALSE)*25,0) -> 11015025 | AG7: =IF(ISNUMBER(VLOOKUP($AC$1*AC7,Data!$C$1:$X$161,21,FALSE)*25)=TRUE,VLOOKUP($AC$1*AC7,Data!$C$1:$X$161,21,FALSE)*25,0) -> 14109825 | AH7: =AE7/AD7 -> 1.1926807 | AI7: =IF(AG7<0, IF(AF7<0,AF7/AG7,-10),IF(AF7<0,10,AG7/AF7)) -> 1.2809617
A8: 7 | B8: =IF(ISNUMBER(VLOOKUP($A$1*A8,Data!$C$1:$D$81,2,FALSE)*25)=TRUE,VLOOKUP($A$1*A8,Data!$C$1:$D$81,2,FALSE)*25,0) -> 463000 | C8: =IF(ISNUMBER(VLOOKUP($A$1*A8,Data!$C$1:$X$81,22,FALSE)*25)=TRUE,VLOOKUP($A$1*A8,Data!$C$1:$X$81,22,FALSE)*25,0) -> 3960475 | D8: =IF(ISNUMBER(VLOOKUP($A$1*A8,Data!$C$1:$X$81,3,FALSE)*25)=TRUE,VLOOKUP($A$1*A8,Data!$C$1:$X$81,3,FALSE)*25,0) -> -336700 | E8: =IF(ISNUMBER(VLOOKUP($A$1*A8,Data!$C$1:$X$81,21,FALSE)*25)=TRUE,VLOOKUP($A$1*A8,Data!$C$1:$X$81,21,FALSE)*25,0) -> 3160925 | F8: =C8/B8 -> 8.5539417 | G8: =IF(E8<0, IF(D8<0,D8/E8,-10),IF(D8<0,10,E8/D8)) -> 10 | H8: 7 | I8: =IF(ISNUMBER(VLOOKUP($H$1*H8,Data!$C$1:$D$81,2,FALSE)*25)=TRUE,VLOOKUP($H$1*H8,Data!$C$1:$D$81,2,FALSE)*25,0) -> 1384375 | J8: =IF(ISNUMBER(VLOOKUP($H$1*H8,Data!$C$1:$X$81,22,FALSE)*25)=TRUE,VLOOKUP($H$1*H8,Data!$C$1:$X$81,22,FALSE)*25,0) -> 7835125 | K8: =IF(ISNUMBER(VLOOKUP($H$1*H8,Data!$C$1:$X$81,3,FALSE)*25)=TRUE,VLOOKUP($H$1*H8,Data!$C$1:$X$81,3,FALSE)*25,0) -> -641825 | L8: =IF(ISNUMBER(VLOOKUP($H$1*H8,Data!$C$1:$X$81,21,FALSE)*25)=TRUE,VLOOKUP($H$1*H8,Data!$C$1:$X$81,21,FALSE)*25,0) -> 6723850 | M8: =J8/I8 -> 5.659684 | N8: =IF(L8<0, IF(K8<0,K8/L8,-10),IF(K8<0,10,L8/K8)) -> 10 | O8: 7 | P8: =IF(ISNUMBER(VLOOKUP($O$1*O8,Data!$C$1:$D$81,2,FALSE)*25)=TRUE,VLOOKUP($O$1*O8,Data!$C$1:$D$81,2,FALSE)*25,0) -> 1881675 | Q8: =IF(ISNUMBER(VLOOKUP($O$1*O8,Data!$C$1:$X$81,22,FALSE)*25)=TRUE,VLOOKUP($O$1*O8,Data!$C$1:$X$81,22,FALSE)*25,0) -> 7772200 | R8: =IF(ISNUMBER(VLOOKUP($O$1*O8,Data!$C$1:$X$81,3,FALSE)*25)=TRUE,VLOOKUP($O$1*O8,Data!$C$1:$X$81,3,FALSE)*25,0) -> 678050 | S8: =IF(ISNUMBER(VLOOKUP($O$1*O8,Data!$C$1:$X$81,21,FALSE)*25)=TRUE,VLOOKUP($O$1*O8,Data!$C$1:$X$81,21,FALSE)*25,0) -> 7423625 | T8: =Q8/P8 -> 4.1304689 | U8: =IF(S8<0, IF(R8<0,R8/S8,-10),IF(R8<0,10,S8/R8)) -> 10.948492 | V8: 7 | W8: =IF(ISNUMBER(VLOOKUP($V$1*V8,Data!$C$1:$D$81,2,FALSE)*25)=TRUE,VLOOKUP($V$1*V8,Data!$C$1:$D$81,2,FALSE)*25,0) -> 6570050 | X8: =IF(ISNUMBER(VLOOKUP($V$1*V8,Data!$C$1:$X$81,22,FALSE)*25)=TRUE,VLOOKUP($V$1*V8,Data!$C$1:$X$81,22,FALSE)*25,0) -> 19784300 | Y8: =IF(ISNUMBER(VLOOKUP($V$1*V8,Data!$C$1:$X$81,3,FALSE)*25)=TRUE,VLOOKUP($V$1*V8,Data!$C$1:$X$81,3,FALSE)*25,0) -> 3826725 | Z8: =IF(ISNUMBER(VLOOKUP($V$1*V8,Data!$C$1:$X$81,21,FALSE)*25)=TRUE,VLOOKUP($V$1*V8,Data!$C$1:$X$81,21,FALSE)*25,0) -> 19118850 | AA8: =X8/W8 -> 3.0112861 | AB8: =IF(Z8<0, IF(Y8<0,Y8/Z8,-10),IF(Y8<0,10,Z8/Y8)) -> 4.996139 | AC8: 7 | AD8: =IF(ISNUMBER(VLOOKUP($AC$1*AC8,Data!$C$1:$D$161,2,FALSE)*25)=TRUE,VLOOKUP($AC$1*AC8,Data!$C$1:$D$161,2,FALSE)*25,0) -> 13561050 | AE8: =IF(ISNUMBER(VLOOKUP($AC$1*AC8,Data!$C$1:$X$161,22,FALSE)*25)=TRUE,VLOOKUP($AC$1*AC8,Data!$C$1:$X$161,22,FALSE)*25,0) -> 12517150 | AF8: =IF(ISNUMBER(VLOOKUP($AC$1*AC8,Data!$C$1:$X$161,3,FALSE)*25)=TRUE,VLOOKUP($AC$1*AC8,Data!$C$1:$X$161,3,FALSE)*25,0) -> 12693075 | AG8: =IF(ISNUMBER(VLOOKUP($AC$1*AC8,Data!$C$1:$X$161,21,FALSE)*25)=TRUE,VLOOKUP($AC$1*AC8,Data!$C$1:$X$161,21,FALSE)*25,0) -> 12454350 | AH8: =AE8/AD8 -> 0.92302218 | AI8: =IF(AG8<0, IF(AF8<0,AF8/AG8,-10),IF(AF8<0,10,AG8/AF8)) -> 0.9811925
A9: 8 | B9: =IF(ISNUMBER(VLOOKUP($A$1*A9,Data!$C$1:$D$81,2,FALSE)*25)=TRUE,VLOOKUP($A$1*A9,Data!$C$1:$D$81,2,FALSE)*25,0) -> 476050 | C9: =IF(ISNUMBER(VLOOKUP($A$1*A9,Data!$C$1:$X$81,22,FALSE)*25)=TRUE,VLOOKUP($A$1*A9,Data!$C$1:$X$81,22,FALSE)*25,0) -> 3950550 | D9: =IF(ISNUMBER(VLOOKUP($A$1*A9,Data!$C$1:$X$81,3,FALSE)*25)=TRUE,VLOOKUP($A$1*A9,Data!$C$1:$X$81,3,FALSE)*25,0) -> -323650 | E9: =IF(ISNUMBER(VLOOKUP($A$1*A9,Data!$C$1:$X$81,21,FALSE)*25)=TRUE,VLOOKUP($A$1*A9,Data!$C$1:$X$81,21,FALSE)*25,0) -> 3151000 | F9: =C9/B9 -> 8.2986031 | G9: =IF(E9<0, IF(D9<0,D9/E9,-10),IF(D9<0,10,E9/D9)) -> 10 | H9: 8 | I9: =IF(ISNUMBER(VLOOKUP($H$1*H9,Data!$C$1:$D$81,2,FALSE)*25)=TRUE,VLOOKUP($H$1*H9,Data!$C$1:$D$81,2,FALSE)*25,0) -> 1472800 | J9: =IF(ISNUMBER(VLOOKUP($H$1*H9,Data!$C$1:$X$81,22,FALSE)*25)=TRUE,VLOOKUP($H$1*H9,Data!$C$1:$X$81,22,FALSE)*25,0) -> 7969500 | K9: =IF(ISNUMBER(VLOOKUP($H$1*H9,Data!$C$1:$X$81,3,FALSE)*25)=TRUE,VLOOKUP($H$1*H9,Data!$C$1:$X$81,3,FALSE)*25,0) -> -553400 | L9: =IF(ISNUMBER(VLOOKUP($H$1*H9,Data!$C$1:$X$81,21,FALSE)*25)=TRUE,VLOOKUP($H$1*H9,Data!$C$1:$X$81,21,FALSE)*25,0) -> 6858225 | M9: =J9/I9 -> 5.4111217 | N9: =IF(L9<0, IF(K9<0,K9/L9,-10),IF(K9<0,10,L9/K9)) -> 10 | O9: 8 | P9: =IF(ISNUMBER(VLOOKUP($O$1*O9,Data!$C$1:$D$81,2,FALSE)*25)=TRUE,VLOOKUP($O$1*O9,Data!$C$1:$D$81,2,FALSE)*25,0) -> 2010950 | Q9: =IF(ISNUMBER(VLOOKUP($O$1*O9,Data!$C$1:$X$81,22,FALSE)*25)=TRUE,VLOOKUP($O$1*O9,Data!$C$1:$X$81,22,FALSE)*25,0) -> 8189025 | R9: =IF(ISNUMBER(VLOOKUP($O$1*O9,Data!$C$1:$X$81,3,FALSE)*25)=TRUE,VLOOKUP($O$1*O9,Data!$C$1:$X$81,3,FALSE)*25,0) -> 807325 | S9: =IF(ISNUMBER(VLOOKUP($O$1*O9,Data!$C$1:$X$81,21,FALSE)*25)=TRUE,VLOOKUP($O$1*O9,Data!$C$1:$X$81,21,FALSE)*25,0) -> 7840450 | T9: =Q9/P9 -> 4.0722171 | U9: =IF(S9<0, IF(R9<0,R9/S9,-10),IF(R9<0,10,S9/R9)) -> 9.7116403 | V9: 8 | W9: =IF(ISNUMBER(VLOOKUP($V$1*V9,Data!$C$1:$D$81,2,FALSE)*25)=TRUE,VLOOKUP($V$1*V9,Data!$C$1:$D$81,2,FALSE)*25,0) -> 7331125 | X9: =IF(ISNUMBER(VLOOKUP($V$1*V9,Data!$C$1:$X$81,22,FALSE)*25)=TRUE,VLOOKUP($V$1*V9,Data!$C$1:$X$81,22,FALSE)*25,0) -> 20109550 | Y9: =IF(ISNUMBER(VLOOKUP($V$1*V9,Data!$C$1:$X$81,3,FALSE)*25)=TRUE,VLOOKUP($V$1*V9,Data!$C$1:$X$81,3,FALSE)*25,0) -> 4587800 | Z9: =IF(ISNUMBER(VLOOKUP($V$1*V9,Data!$C$1:$X$81,21,FALSE)*25)=TRUE,VLOOKUP($V$1*V9,Data!$C$1:$X$81,21,FALSE)*25,0) -> 19444100 | AA9: =X9/W9 -> 2.7430374 | AB9: =IF(Z9<0, IF(Y9<0,Y9/Z9,-10),IF(Y9<0,10,Z9/Y9)) -> 4.2382188 | AC9: 8 | AD9: =IF(ISNUMBER(VLOOKUP($AC$1*AC9,Data!$C$1:$D$161,2,FALSE)*25)=TRUE,VLOOKUP($AC$1*AC9,Data!$C$1:$D$161,2,FALSE)*25,0) -> 14697950 | AE9: =IF(ISNUMBER(VLOOKUP($AC$1*AC9,Data!$C$1:$X$161,22,FALSE)*25)=TRUE,VLOOKUP($AC$1*AC9,Data!$C$1:$X$161,22,FALSE)*25,0) -> 11022300 | AF9: =IF(ISNUMBER(VLOOKUP($AC$1*AC9,Data!$C$1:$X$161,3,FALSE)*25)=TRUE,VLOOKUP($AC$1*AC9,Data!$C$1:$X$161,3,FALSE)*25,0) -> 13829975 | AG9: =IF(ISNUMBER(VLOOKUP($AC$1*AC9,Data!$C$1:$X$161,21,FALSE)*25)=TRUE,VLOOKUP($AC$1*AC9,Data!$C$1:$X$161,21,FALSE)*25,0) -> 10959500 | AH9: =AE9/AD9 -> 0.74992091 | AI9: =IF(AG9<0, IF(AF9<0,AF9/AG9,-10),IF(AF9<0,10,AG9/AF9)) -> 0.79244539
AC10: 9 | AD10: =IF(ISNUMBER(VLOOKUP($AC$1*AC10,Data!$C$1:$D$161,2,FALSE)*25)=TRUE,VLOOKUP($AC$1*AC10,Data!$C$1:$D$161,2,FALSE)*25,0) -> 11893000 | AE10: =IF(ISNUMBER(VLOOKUP($AC$1*AC10,Data!$C$1:$X$161,22,FALSE)*25)=TRUE,VLOOKUP($AC$1*AC10,Data!$C$1:$X$161,22,FALSE)*25,0) -> 13897800 | AF10: =IF(ISNUMBER(VLOOKUP($AC$1*AC10,Data!$C$1:$X$161,3,FALSE)*25)=TRUE,VLOOKUP($AC$1*AC10,Data!$C$1:$X$161,3,FALSE)*25,0) -> 11025025 | AG10: =IF(ISNUMBER(VLOOKUP($AC$1*AC10,Data!$C$1:$X$161,21,FALSE)*25)=TRUE,VLOOKUP($AC$1*AC10,Data!$C$1:$X$161,21,FALSE)*25,0) -> 13835000 | AH10: =AE10/AD10 -> 1.1685697 | AI10: =IF(AG10<0, IF(AF10<0,AF10/AG10,-10),IF(AF10<0,10,AG10/AF10)) -> 1.2548724
AC11: 10 | AD11: =IF(ISNUMBER(VLOOKUP($AC$1*AC11,Data!$C$1:$D$161,2,FALSE)*25)=TRUE,VLOOKUP($AC$1*AC11,Data!$C$1:$D$161,2,FALSE)*25,0) -> 11262825 | AE11: =IF(ISNUMBER(VLOOKUP($AC$1*AC11,Data!$C$1:$X$161,22,FALSE)*25)=TRUE,VLOOKUP($AC$1*AC11,Data!$C$1:$X$161,22,FALSE)*25,0) -> 14112975 | AF11: =IF(ISNUMBER(VLOOKUP($AC$1*AC11,Data!$C$1:$X$161,3,FALSE)*25)=TRUE,VLOOKUP($AC$1*AC11,Data!$C$1:$X$161,3,FALSE)*25,0) -> 10394850 | AG11: =IF(ISNUMBER(VLOOKUP($AC$1*AC11,Data!$C$1:$X$161,21,FALSE)*25)=TRUE,VLOOKUP($AC$1*AC11,Data!$C$1:$X$161,21,FALSE)*25,0) -> 14050175 | AH11: =AE11/AD11 -> 1.2530582 | AI11: =IF(AG11<0, IF(AF11<0,AF11/AG11,-10),IF(AF11<0,10,AG11/AF11)) -> 1.3516477
AC12: 11 | AD12: =IF(ISNUMBER(VLOOKUP($AC$1*AC12,Data!$C$1:$D$161,2,FALSE)*25)=TRUE,VLOOKUP($AC$1*AC12,Data!$C$1:$D$161,2,FALSE)*25,0) -> 10241100 | AE12: =IF(ISNUMBER(VLOOKUP($AC$1*AC12,Data!$C$1:$X$161,22,FALSE)*25)=TRUE,VLOOKUP($AC$1*AC12,Data!$C$1:$X$161,22,FALSE)*25,0) -> 14051450 | AF12: =IF(ISNUMBER(VLOOKUP($AC$1*AC12,Data!$C$1:$X$161,3,FALSE)*25)=TRUE,VLOOKUP($AC$1*AC12,Data!$C$1:$X$161,3,FALSE)*25,0) -> 9373125 | AG12: =IF(ISNUMBER(VLOOKUP($AC$1*AC12,Data!$C$1:$X$161,21,FALSE)*25)=TRUE,VLOOKUP($AC$1*AC12,Data!$C$1:$X$161,21,FALSE)*25,0) -> 13988650 | AH12: =AE12/AD12 -> 1.3720645 | AI12: =IF(AG12<0, IF(AF12<0,AF12/AG12,-10),IF(AF12<0,10,AG12/AF12)) -> 1.4924212
AC13: 12 | AD13: =IF(ISNUMBER(VLOOKUP($AC$1*AC13,Data!$C$1:$D$161,2,FALSE)*25)=TRUE,VLOOKUP($AC$1*AC13,Data!$C$1:$D$161,2,FALSE)*25,0) -> 9445225 | AE13: =IF(ISNUMBER(VLOOKUP($AC$1*AC13,Data!$C$1:$X$161,22,FALSE)*25)=TRUE,VLOOKUP($AC$1*AC13,Data!$C$1:$X$161,22,FALSE)*25,0) -> 14170950 | AF13: =IF(ISNUMBER(VLOOKUP($AC$1*AC13,Data!$C$1:$X$161,3,FALSE)*25)=TRUE,VLOOKUP($AC$1*AC13,Data!$C$1:$X$161,3,FALSE)*25,0) -> 8577250 | AG13: =IF(ISNUMBER(VLOOKUP($AC$1*AC13,Data!$C$1:$X$161,21,FALSE)*25)=TRUE,VLOOKUP($AC$1*AC13,Data!$C$1:$X$161,21,FALSE)*25,0) -> 14108150 | AH13: =AE13/AD13 -> 1.5003295 | AI13: =IF(AG13<0, IF(AF13<0,AF13/AG13,-10),IF(AF13<0,10,AG13/AF13)) -> 1.6448337
AC14: 13 | AD14: =IF(ISNUMBER(VLOOKUP($AC$1*AC14,Data!$C$1:$D$161,2,FALSE)*25)=TRUE,VLOOKUP($AC$1*AC14,Data!$C$1:$D$161,2,FALSE)*25,0) -> 9309475 | AE14: =IF(ISNUMBER(VLOOKUP($AC$1*AC14,Data!$C$1:$X$161,22,FALSE)*25)=TRUE,VLOOKUP($AC$1*AC14,Data!$C$1:$X$161,22,FALSE)*25,0) -> 13916500 | AF14: =IF(ISNUMBER(VLOOKUP($AC$1*AC14,Data!$C$1:$X$161,3,FALSE)*25)=TRUE,VLOOKUP($AC$1*AC14,Data!$C$1:$X$161,3,FALSE)*25,0) -> 8441500 | AG14: =IF(ISNUMBER(VLOOKUP($AC$1*AC14,Data!$C$1:$X$161,21,FALSE)*25)=TRUE,VLOOKUP($AC$1*AC14,Data!$C$1:$X$161,21,FALSE)*25,0) -> 13853700 | AH14: =AE14/AD14 -> 1.4948748 | AI14: =IF(AG14<0, IF(AF14<0,AF14/AG14,-10),IF(AF14<0,10,AG14/AF14)) -> 1.641142
AC15: 14 | AD15: =IF(ISNUMBER(VLOOKUP($AC$1*AC15,Data!$C$1:$D$161,2,FALSE)*25)=TRUE,VLOOKUP($AC$1*AC15,Data!$C$1:$D$161,2,FALSE)*25,0) -> 8696050 | AE15: =IF(ISNUMBER(VLOOKUP($AC$1*AC15,Data!$C$1:$X$161,22,FALSE)*25)=TRUE,VLOOKUP($AC$1*AC15,Data!$C$1:$X$161,22,FALSE)*25,0) -> 13194475 | AF15: =IF(ISNUMBER(VLOOKUP($AC$1*AC15,Data!$C$1:$X$161,3,FALSE)*25)=TRUE,VLOOKUP($AC$1*AC15,Data!$C$1:$X$161,3,FALSE)*25,0) -> 7828075 | AG15: =IF(ISNUMBER(VLOOKUP($AC$1*AC15,Data!$C$1:$X$161,21,FALSE)*25)=TRUE,VLOOKUP($AC$1*AC15,Data!$C$1:$X$161,21,FALSE)*25,0) -> 13131675 | AH15: =AE15/AD15 -> 1.5172952 | AI15: =IF(AG15<0, IF(AF15<0,AF15/AG15,-10),IF(AF15<0,10,AG15/AF15)) -> 1.6775101
AC16: 15 | AD16: =IF(ISNUMBER(VLOOKUP($AC$1*AC16,Data!$C$1:$D$161,2,FALSE)*25)=TRUE,VLOOKUP($AC$1*AC16,Data!$C$1:$D$161,2,FALSE)*25,0) -> 9002350 | AE16: =IF(ISNUMBER(VLOOKUP($AC$1*AC16,Data!$C$1:$X$161,22,FALSE)*25)=TRUE,VLOOKUP($AC$1*AC16,Data!$C$1:$X$161,22,FALSE)*25,0) -> 12519300 | AF16: =IF(ISNUMBER(VLOOKUP($AC$1*AC16,Data!$C$1:$X$161,3,FALSE)*25)=TRUE,VLOOKUP($AC$1*AC16,Data!$C$1:$X$161,3,FALSE)*25,0) -> 8134375 | AG16: =IF(ISNUMBER(VLOOKUP($AC$1*AC16,Data!$C$1:$X$161,21,FALSE)*25)=TRUE,VLOOKUP($AC$1*AC16,Data!$C$1:$X$161,21,FALSE)*25,0) -> 12456500 | AH16: =AE16/AD16 -> 1.3906702 | AI16: =IF(AG16<0, IF(AF16<0,AF16/AG16,-10),IF(AF16<0,10,AG16/AF16)) -> 1.5313408
AC17: 16 | AD17: =IF(ISNUMBER(VLOOKUP($AC$1*AC17,Data!$C$1:$D$161,2,FALSE)*25)=TRUE,VLOOKUP($AC$1*AC17,Data!$C$1:$D$161,2,FALSE)*25,0) -> 13776700 | AE17: =IF(ISNUMBER(VLOOKUP($AC$1*AC17,Data!$C$1:$X$161,22,FALSE)*25)=TRUE,VLOOKUP($AC$1*AC17,Data!$C$1:$X$161,22,FALSE)*25,0) -> 9700800 | AF17: =IF(ISNUMBER(VLOOKUP($AC$1*AC17,Data!$C$1:$X$161,3,FALSE)*25)=TRUE,VLOOKUP($AC$1*AC17,Data!$C$1:$X$161,3,FALSE)*25,0) -> 12908725 | AG17: =IF(ISNUMBER(VLOOKUP($AC$1*AC17,Data!$C$1:$X$161,21,FALSE)*25)=TRUE,VLOOKUP($AC$1*AC17,Data!$C$1:$X$161,21,FALSE)*25,0) -> 9638000 | AH17: =AE17/AD17 -> 0.7041454 | AI17: =IF(AG17<0, IF(AF17<0,AF17/AG17,-10),IF(AF17<0,10,AG17/AF17)) -> 0.7466268
A19: =Entry!$A$2+250 -> 24800 | B19: Call OI | C19: Put OI | D19: Change Call | E19: Change Put | F19: PCR | G19: Change PCR | H19: =Entry!$A$2+200 -> 24750 | I19: Call OI | J19: Put OI | K19: Change Call | L19: Change Put | M19: PCR | N19: Change PCR | O19: =Entry!$A$2+150 -> 24700 | P19: Call OI | Q19: Put OI | R19: Change Call | S19: Change Put | T19: PCR | U19: Change PCR | V19: =Entry!$A$2+100 -> 24650 | W19: Call OI | X19: Put OI | Y19: Change Call | Z19: Change Put | AA19: PCR | AB19: Change PCR | AC19: =Entry!$A$2+50 -> 24600 | AD19: Call OI | AE19: Put OI | AF19: Change Call | AG19: Change Put | AH19: PCR | AI19: Change PCR
A20: 1 | B20: =IF(ISNUMBER(VLOOKUP($A$19*A20,Data!$C$1:$D$81,2,FALSE)*25)=TRUE,VLOOKUP($A$19*A20,Data!$C$1:$D$81,2,FALSE)*25,0) -> 0 | C20: =IF(ISNUMBER(VLOOKUP($A$19*A20,Data!$C$1:$X$81,22,FALSE)*25)=TRUE,VLOOKUP($A$19*A20,Data!$C$1:$X$81,22,FALSE)*25,0) -> 0 | D20: =IF(ISNUMBER(VLOOKUP($A$19*A20,Data!$C$1:$X$81,3,FALSE)*25)=TRUE,VLOOKUP($A$19*A20,Data!$C$1:$X$81,3,FALSE)*25,0) -> 0 | E20: =IF(ISNUMBER(VLOOKUP($A$19*A20,Data!$C$1:$X$81,21,FALSE)*25)=TRUE,VLOOKUP($A$19*A20,Data!$C$1:$X$81,21,FALSE)*25,0) -> 0 | F20: =C20/B20 -> #DIV/0! | G20: =IF(E20<0, IF(D20<0,D20/E20,-10),IF(D20<0,10,E20/D20)) -> #DIV/0! | H20: 1 | I20: =IF(ISNUMBER(VLOOKUP($H$19*H20,Data!$C$1:$D$81,2,FALSE)*25)=TRUE,VLOOKUP($H$19*H20,Data!$C$1:$D$81,2,FALSE)*25,0) -> 0 | J20: =IF(ISNUMBER(VLOOKUP($H$19*H20,Data!$C$1:$X$81,22,FALSE)*25)=TRUE,VLOOKUP($H$19*H20,Data!$C$1:$X$81,22,FALSE)*25,0) -> 0 | K20: =IF(ISNUMBER(VLOOKUP($H$19*H20,Data!$C$1:$X$81,3,FALSE)*25)=TRUE,VLOOKUP($H$19*H20,Data!$C$1:$X$81,3,FALSE)*25,0) -> 0 | L20: =IF(ISNUMBER(VLOOKUP($H$19*H20,Data!$C$1:$X$81,21,FALSE)*25)=TRUE,VLOOKUP($H$19*H20,Data!$C$1:$X$81,21,FALSE)*25,0) -> 0 | M20: =J20/I20 -> #DIV/0! | N20: =IF(L20<0, IF(K20<0,K20/L20,-10),IF(K20<0,10,L20/K20)) -> #DIV/0! | O20: 1 | P20: =IF(ISNUMBER(VLOOKUP($O$19*O20,Data!$C$1:$D$81,2,FALSE)*25)=TRUE,VLOOKUP($O$19*O20,Data!$C$1:$D$81,2,FALSE)*25,0) -> 0 | Q20: =IF(ISNUMBER(VLOOKUP($O$19*O20,Data!$C$1:$X$81,22,FALSE)*25)=TRUE,VLOOKUP($O$19*O20,Data!$C$1:$X$81,22,FALSE)*25,0) -> 0 | R20: =IF(ISNUMBER(VLOOKUP($O$19*O20,Data!$C$1:$X$81,3,FALSE)*25)=TRUE,VLOOKUP($O$19*O20,Data!$C$1:$X$81,3,FALSE)*25,0) -> 0 | S20: =IF(ISNUMBER(VLOOKUP($O$19*O20,Data!$C$1:$X$81,21,FALSE)*25)=TRUE,VLOOKUP($O$19*O20,Data!$C$1:$X$81,21,FALSE)*25,0) -> 0 | T20: =Q20/P20 -> #DIV/0! | U20: =IF(S20<0, IF(R20<0,R20/S20,-10),IF(R20<0,10,S20/R20)) -> #DIV/0! | V20: 1 | W20: =IF(ISNUMBER(VLOOKUP($V$19*V20,Data!$C$1:$D$81,2,FALSE)*25)=TRUE,VLOOKUP($V$19*V20,Data!$C$1:$D$81,2,FALSE)*25,0) -> 0 | X20: =IF(ISNUMBER(VLOOKUP($V$19*V20,Data!$C$1:$X$81,22,FALSE)*25)=TRUE,VLOOKUP($V$19*V20,Data!$C$1:$X$81,22,FALSE)*25,0) -> 0 | Y20: =IF(ISNUMBER(VLOOKUP($V$19*V20,Data!$C$1:$X$81,3,FALSE)*25)=TRUE,VLOOKUP($V$19*V20,Data!$C$1:$X$81,3,FALSE)*25,0) -> 0 | Z20: =IF(ISNUMBER(VLOOKUP($V$19*V20,Data!$C$1:$X$81,21,FALSE)*25)=TRUE,VLOOKUP($V$19*V20,Data!$C$1:$X$81,21,FALSE)*25,0) -> 0 | AA20: =X20/W20 -> #DIV/0! | AB20: =IF(Z20<0, IF(Y20<0,Y20/Z20,-10),IF(Y20<0,10,Z20/Y20)) -> #DIV/0! | AC20: 1 | AD20: =IF(ISNUMBER(VLOOKUP($AC$19*AC20,Data!$C$1:$D$161,2,FALSE)*25)=TRUE,VLOOKUP($AC$19*AC20,Data!$C$1:$D$161,2,FALSE)*25,0) -> 0 | AE20: =IF(ISNUMBER(VLOOKUP($AC$19*AC20,Data!$C$1:$X$161,22,FALSE)*25)=TRUE,VLOOKUP($AC$19*AC20,Data!$C$1:$X$161,22,FALSE)*25,0) -> 0 | AF20: =IF(ISNUMBER(VLOOKUP($AC$19*AC20,Data!$C$1:$X$161,3,FALSE)*25)=TRUE,VLOOKUP($AC$19*AC20,Data!$C$1:$X$161,3,FALSE)*25,0) -> 0 | AG20: =IF(ISNUMBER(VLOOKUP($AC$19*AC20,Data!$C$1:$X$161,21,FALSE)*25)=TRUE,VLOOKUP($AC$19*AC20,Data!$C$1:$X$161,21,FALSE)*25,0) -> 0 | AH20: =AE20/AD20 -> #DIV/0! | AI20: =IF(AG20<0, IF(AF20<0,AF20/AG20,-10),IF(AF20<0,10,AG20/AF20)) -> #DIV/0!
A21: 2 | B21: =IF(ISNUMBER(VLOOKUP($A$19*A21,Data!$C$1:$D$81,2,FALSE)*25)=TRUE,VLOOKUP($A$19*A21,Data!$C$1:$D$81,2,FALSE)*25,0) -> 4863475 | C21: =IF(ISNUMBER(VLOOKUP($A$19*A21,Data!$C$1:$X$81,22,FALSE)*25)=TRUE,VLOOKUP($A$19*A21,Data!$C$1:$X$81,22,FALSE)*25,0) -> 165375 | D21: =IF(ISNUMBER(VLOOKUP($A$19*A21,Data!$C$1:$X$81,3,FALSE)*25)=TRUE,VLOOKUP($A$19*A21,Data!$C$1:$X$81,3,FALSE)*25,0) -> 2186450 | E21: =IF(ISNUMBER(VLOOKUP($A$19*A21,Data!$C$1:$X$81,21,FALSE)*25)=TRUE,VLOOKUP($A$19*A21,Data!$C$1:$X$81,21,FALSE)*25,0) -> 130175 | F21: =C21/B21 -> 0.034003465 | G21: =IF(E21<0, IF(D21<0,D21/E21,-10),IF(D21<0,10,E21/D21)) -> 0.059537149 | H21: 2 | I21: =IF(ISNUMBER(VLOOKUP($H$19*H21,Data!$C$1:$D$81,2,FALSE)*25)=TRUE,VLOOKUP($H$19*H21,Data!$C$1:$D$81,2,FALSE)*25,0) -> 2944075 | J21: =IF(ISNUMBER(VLOOKUP($H$19*H21,Data!$C$1:$X$81,22,FALSE)*25)=TRUE,VLOOKUP($H$19*H21,Data!$C$1:$X$81,22,FALSE)*25,0) -> 142975 | K21: =IF(ISNUMBER(VLOOKUP($H$19*H21,Data!$C$1:$X$81,3,FALSE)*25)=TRUE,VLOOKUP($H$19*H21,Data!$C$1:$X$81,3,FALSE)*25,0) -> 2059375 | L21: =IF(ISNUMBER(VLOOKUP($H$19*H21,Data!$C$1:$X$81,21,FALSE)*25)=TRUE,VLOOKUP($H$19*H21,Data!$C$1:$X$81,21,FALSE)*25,0) -> 127575 | M21: =J21/I21 -> 0.048563641 | N21: =IF(L21<0, IF(K21<0,K21/L21,-10),IF(K21<0,10,L21/K21)) -> 0.061948407 | O21: 2 | P21: =IF(ISNUMBER(VLOOKUP($O$19*O21,Data!$C$1:$D$81,2,FALSE)*25)=TRUE,VLOOKUP($O$19*O21,Data!$C$1:$D$81,2,FALSE)*25,0) -> 4654475 | Q21: =IF(ISNUMBER(VLOOKUP($O$19*O21,Data!$C$1:$X$81,22,FALSE)*25)=TRUE,VLOOKUP($O$19*O21,Data!$C$1:$X$81,22,FALSE)*25,0) -> 638375 | R21: =IF(ISNUMBER(VLOOKUP($O$19*O21,Data!$C$1:$X$81,3,FALSE)*25)=TRUE,VLOOKUP($O$19*O21,Data!$C$1:$X$81,3,FALSE)*25,0) -> 3031725 | S21: =IF(ISNUMBER(VLOOKUP($O$19*O21,Data!$C$1:$X$81,21,FALSE)*25)=TRUE,VLOOKUP($O$19*O21,Data!$C$1:$X$81,21,FALSE)*25,0) -> 541700 | T21: =Q21/P21 -> 0.13715295 | U21: =IF(S21<0, IF(R21<0,R21/S21,-10),IF(R21<0,10,S21/R21)) -> 0.17867716 | V21: 2 | W21: =IF(ISNUMBER(VLOOKUP($V$19*V21,Data!$C$1:$D$81,2,FALSE)*25)=TRUE,VLOOKUP($V$19*V21,Data!$C$1:$D$81,2,FALSE)*25,0) -> 5104225 | X21: =IF(ISNUMBER(VLOOKUP($V$19*V21,Data!$C$1:$X$81,22,FALSE)*25)=TRUE,VLOOKUP($V$19*V21,Data!$C$1:$X$81,22,FALSE)*25,0) -> 1269375 | Y21: =IF(ISNUMBER(VLOOKUP($V$19*V21,Data!$C$1:$X$81,3,FALSE)*25)=TRUE,VLOOKUP($V$19*V21,Data!$C$1:$X$81,3,FALSE)*25,0) -> 4159200 | Z21: =IF(ISNUMBER(VLOOKUP($V$19*V21,Data!$C$1:$X$81,21,FALSE)*25)=TRUE,VLOOKUP($V$19*V21,Data!$C$1:$X$81,21,FALSE)*25,0) -> 1247425 | AA21: =X21/W21 -> 0.24869104 | AB21: =IF(Z21<0, IF(Y21<0,Y21/Z21,-10),IF(Y21<0,10,Z21/Y21)) -> 0.29991946 | AC21: 2 | AD21: =IF(ISNUMBER(VLOOKUP($AC$19*AC21,Data!$C$1:$D$161,2,FALSE)*25)=TRUE,VLOOKUP($AC$19*AC21,Data!$C$1:$D$161,2,FALSE)*25,0) -> 15041650 | AE21: =IF(ISNUMBER(VLOOKUP($AC$19*AC21,Data!$C$1:$X$161,22,FALSE)*25)=TRUE,VLOOKUP($AC$19*AC21,Data!$C$1:$X$161,22,FALSE)*25,0) -> 6477425 | AF21: =IF(ISNUMBER(VLOOKUP($AC$19*AC21,Data!$C$1:$X$161,3,FALSE)*25)=TRUE,VLOOKUP($AC$19*AC21,Data!$C$1:$X$161,3,FALSE)*25,0) -> 12758700 | AG21: =IF(ISNUMBER(VLOOKUP($AC$19*AC21,Data!$C$1:$X$161,21,FALSE)*25)=TRUE,VLOOKUP($AC$19*AC21,Data!$C$1:$X$161,21,FALSE)*25,0) -> 6371875 | AH21: =AE21/AD21 -> 0.43063261 | AI21: =IF(AG21<0, IF(AF21<0,AF21/AG21,-10),IF(AF21<0,10,AG21/AF21)) -> 0.49941413
A22: 3 | B22: =IF(ISNUMBER(VLOOKUP($A$19*A22,Data!$C$1:$D$81,2,FALSE)*25)=TRUE,VLOOKUP($A$19*A22,Data!$C$1:$D$81,2,FALSE)*25,0) -> 5135175 | C22: =IF(ISNUMBER(VLOOKUP($A$19*A22,Data!$C$1:$X$81,22,FALSE)*25)=TRUE,VLOOKUP($A$19*A22,Data!$C$1:$X$81,22,FALSE)*25,0) -> 177025 | D22: =IF(ISNUMBER(VLOOKUP($A$19*A22,Data!$C$1:$X$81,3,FALSE)*25)=TRUE,VLOOKUP($A$19*A22,Data!$C$1:$X$81,3,FALSE)*25,0) -> 2458150 | E22: =IF(ISNUMBER(VLOOKUP($A$19*A22,Data!$C$1:$X$81,21,FALSE)*25)=TRUE,VLOOKUP($A$19*A22,Data!$C$1:$X$81,21,FALSE)*25,0) -> 141825 | F22: =C22/B22 -> 0.034473022 | G22: =IF(E22<0, IF(D22<0,D22/E22,-10),IF(D22<0,10,E22/D22)) -> 0.057695828 | H22: 3 | I22: =IF(ISNUMBER(VLOOKUP($H$19*H22,Data!$C$1:$D$81,2,FALSE)*25)=TRUE,VLOOKUP($H$19*H22,Data!$C$1:$D$81,2,FALSE)*25,0) -> 3060925 | J22: =IF(ISNUMBER(VLOOKUP($H$19*H22,Data!$C$1:$X$81,22,FALSE)*25)=TRUE,VLOOKUP($H$19*H22,Data!$C$1:$X$81,22,FALSE)*25,0) -> 152075 | K22: =IF(ISNUMBER(VLOOKUP($H$19*H22,Data!$C$1:$X$81,3,FALSE)*25)=TRUE,VLOOKUP($H$19*H22,Data!$C$1:$X$81,3,FALSE)*25,0) -> 2176225 | L22: =IF(ISNUMBER(VLOOKUP($H$19*H22,Data!$C$1:$X$81,21,FALSE)*25)=TRUE,VLOOKUP($H$19*H22,Data!$C$1:$X$81,21,FALSE)*25,0) -> 136675 | M22: =J22/I22 -> 0.049682694 | N22: =IF(L22<0, IF(K22<0,K22/L22,-10),IF(K22<0,10,L22/K22)) -> 0.062803708 | O22: 3 | P22: =IF(ISNUMBER(VLOOKUP($O$19*O22,Data!$C$1:$D$81,2,FALSE)*25)=TRUE,VLOOKUP($O$19*O22,Data!$C$1:$D$81,2,FALSE)*25,0) -> 5051650 | Q22: =IF(ISNUMBER(VLOOKUP($O$19*O22,Data!$C$1:$X$81,22,FALSE)*25)=TRUE,VLOOKUP($O$19*O22,Data!$C$1:$X$81,22,FALSE)*25,0) -> 737650 | R22: =IF(ISNUMBER(VLOOKUP($O$19*O22,Data!$C$1:$X$81,3,FALSE)*25)=TRUE,VLOOKUP($O$19*O22,Data!$C$1:$X$81,3,FALSE)*25,0) -> 3428900 | S22: =IF(ISNUMBER(VLOOKUP($O$19*O22,Data!$C$1:$X$81,21,FALSE)*25)=TRUE,VLOOKUP($O$19*O22,Data!$C$1:$X$81,21,FALSE)*25,0) -> 640975 | T22: =Q22/P22 -> 0.1460216 | U22: =IF(S22<0, IF(R22<0,R22/S22,-10),IF(R22<0,10,S22/R22)) -> 0.18693313 | V22: 3 | W22: =IF(ISNUMBER(VLOOKUP($V$19*V22,Data!$C$1:$D$81,2,FALSE)*25)=TRUE,VLOOKUP($V$19*V22,Data!$C$1:$D$81,2,FALSE)*25,0) -> 5313500 | X22: =IF(ISNUMBER(VLOOKUP($V$19*V22,Data!$C$1:$X$81,22,FALSE)*25)=TRUE,VLOOKUP($V$19*V22,Data!$C$1:$X$81,22,FALSE)*25,0) -> 1554150 | Y22: =IF(ISNUMBER(VLOOKUP($V$19*V22,Data!$C$1:$X$81,3,FALSE)*25)=TRUE,VLOOKUP($V$19*V22,Data!$C$1:$X$81,3,FALSE)*25,0) -> 4368475 | Z22: =IF(ISNUMBER(VLOOKUP($V$19*V22,Data!$C$1:$X$81,21,FALSE)*25)=TRUE,VLOOKUP($V$19*V22,Data!$C$1:$X$81,21,FALSE)*25,0) -> 1532200 | AA22: =X22/W22 -> 0.29249083 | AB22: =IF(Z22<0, IF(Y22<0,Y22/Z22,-10),IF(Y22<0,10,Z22/Y22)) -> 0.35074025 | AC22: 3 | AD22: =IF(ISNUMBER(VLOOKUP($AC$19*AC22,Data!$C$1:$D$161,2,FALSE)*25)=TRUE,VLOOKUP($AC$19*AC22,Data!$C$1:$D$161,2,FALSE)*25,0) -> 16722800 | AE22: =IF(ISNUMBER(VLOOKUP($AC$19*AC22,Data!$C$1:$X$161,22,FALSE)*25)=TRUE,VLOOKUP($AC$19*AC22,Data!$C$1:$X$161,22,FALSE)*25,0) -> 7115275 | AF22: =IF(ISNUMBER(VLOOKUP($AC$19*AC22,Data!$C$1:$X$161,3,FALSE)*25)=TRUE,VLOOKUP($AC$19*AC22,Data!$C$1:$X$161,3,FALSE)*25,0) -> 14439850 | AG22: =IF(ISNUMBER(VLOOKUP($AC$19*AC22,Data!$C$1:$X$161,21,FALSE)*25)=TRUE,VLOOKUP($AC$19*AC22,Data!$C$1:$X$161,21,FALSE)*25,0) -> 7009725 | AH22: =AE22/AD22 -> 0.42548347 | AI22: =IF(AG22<0, IF(AF22<0,AF22/AG22,-10),IF(AF22<0,10,AG22/AF22)) -> 0.48544306
A23: 4 | B23: =IF(ISNUMBER(VLOOKUP($A$19*A23,Data!$C$1:$D$81,2,FALSE)*25)=TRUE,VLOOKUP($A$19*A23,Data!$C$1:$D$81,2,FALSE)*25,0) -> 0 | C23: =IF(ISNUMBER(VLOOKUP($A$19*A23,Data!$C$1:$X$81,22,FALSE)*25)=TRUE,VLOOKUP($A$19*A23,Data!$C$1:$X$81,22,FALSE)*25,0) -> 0 | D23: =IF(ISNUMBER(VLOOKUP($A$19*A23,Data!$C$1:$X$81,3,FALSE)*25)=TRUE,VLOOKUP($A$19*A23,Data!$C$1:$X$81,3,FALSE)*25,0) -> 0 | E23: =IF(ISNUMBER(VLOOKUP($A$19*A23,Data!$C$1:$X$81,21,FALSE)*25)=TRUE,VLOOKUP($A$19*A23,Data!$C$1:$X$81,21,FALSE)*25,0) -> 0 | F23: =C23/B23 -> #DIV/0! | G23: =IF(E23<0, IF(D23<0,D23/E23,-10),IF(D23<0,10,E23/D23)) -> #DIV/0! | H23: 4 | I23: =IF(ISNUMBER(VLOOKUP($H$19*H23,Data!$C$1:$D$81,2,FALSE)*25)=TRUE,VLOOKUP($H$19*H23,Data!$C$1:$D$81,2,FALSE)*25,0) -> 3060925 | J23: =IF(ISNUMBER(VLOOKUP($H$19*H23,Data!$C$1:$X$81,22,FALSE)*25)=TRUE,VLOOKUP($H$19*H23,Data!$C$1:$X$81,22,FALSE)*25,0) -> 152075 | K23: =IF(ISNUMBER(VLOOKUP($H$19*H23,Data!$C$1:$X$81,3,FALSE)*25)=TRUE,VLOOKUP($H$19*H23,Data!$C$1:$X$81,3,FALSE)*25,0) -> 2176225 | L23: =IF(ISNUMBER(VLOOKUP($H$19*H23,Data!$C$1:$X$81,21,FALSE)*25)=TRUE,VLOOKUP($H$19*H23,Data!$C$1:$X$81,21,FALSE)*25,0) -> 136675 | M23: =J23/I23 -> 0.049682694 | N23: =IF(L23<0, IF(K23<0,K23/L23,-10),IF(K23<0,10,L23/K23)) -> 0.062803708 | O23: 4 | P23: =IF(ISNUMBER(VLOOKUP($O$19*O23,Data!$C$1:$D$81,2,FALSE)*25)=TRUE,VLOOKUP($O$19*O23,Data!$C$1:$D$81,2,FALSE)*25,0) -> 5051650 | Q23: =IF(ISNUMBER(VLOOKUP($O$19*O23,Data!$C$1:$X$81,22,FALSE)*25)=TRUE,VLOOKUP($O$19*O23,Data!$C$1:$X$81,22,FALSE)*25,0) -> 737650 | R23: =IF(ISNUMBER(VLOOKUP($O$19*O23,Data!$C$1:$X$81,3,FALSE)*25)=TRUE,VLOOKUP($O$19*O23,Data!$C$1:$X$81,3,FALSE)*25,0) -> 3428900 | S23: =IF(ISNUMBER(VLOOKUP($O$19*O23,Data!$C$1:$X$81,21,FALSE)*25)=TRUE,VLOOKUP($O$19*O23,Data!$C$1:$X$81,21,FALSE)*25,0) -> 640975 | T23: =Q23/P23 -> 0.1460216 | U23: =IF(S23<0, IF(R23<0,R23/S23,-10),IF(R23<0,10,S23/R23)) -> 0.18693313 | V23: 4 | W23: =IF(ISNUMBER(VLOOKUP($V$19*V23,Data!$C$1:$D$81,2,FALSE)*25)=TRUE,VLOOKUP($V$19*V23,Data!$C$1:$D$81,2,FALSE)*25,0) -> 5313500 | X23: =IF(ISNUMBER(VLOOKUP($V$19*V23,Data!$C$1:$X$81,22,FALSE)*25)=TRUE,VLOOKUP($V$19*V23,Data!$C$1:$X$81,22,FALSE)*25,0) -> 1554150 | Y23: =IF(ISNUMBER(VLOOKUP($V$19*V23,Data!$C$1:$X$81,3,FALSE)*25)=TRUE,VLOOKUP($V$19*V23,Data!$C$1:$X$81,3,FALSE)*25,0) -> 4368475 | Z23: =IF(ISNUMBER(VLOOKUP($V$19*V23,Data!$C$1:$X$81,21,FALSE)*25)=TRUE,VLOOKUP($V$19*V23,Data!$C$1:$X$81,21,FALSE)*25,0) -> 1532200 | AA23: =X23/W23 -> 0.29249083 | AB23: =IF(Z23<0, IF(Y23<0,Y23/Z23,-10),IF(Y23<0,10,Z23/Y23)) -> 0.35074025 | AC23: 4 | AD23: =IF(ISNUMBER(VLOOKUP($AC$19*AC23,Data!$C$1:$D$161,2,FALSE)*25)=TRUE,VLOOKUP($AC$19*AC23,Data!$C$1:$D$161,2,FALSE)*25,0) -> 16722800 | AE23: =IF(ISNUMBER(VLOOKUP($AC$19*AC23,Data!$C$1:$X$161,22,FALSE)*25)=TRUE,VLOOKUP($AC$19*AC23,Data!$C$1:$X$161,22,FALSE)*25,0) -> 7115275 | AF23: =IF(ISNUMBER(VLOOKUP($AC$19*AC23,Data!$C$1:$X$161,3,FALSE)*25)=TRUE,VLOOKUP($AC$19*AC23,Data!$C$1:$X$161,3,FALSE)*25,0) -> 14439850 | AG23: =IF(ISNUMBER(VLOOKUP($AC$19*AC23,Data!$C$1:$X$161,21,FALSE)*25)=TRUE,VLOOKUP($AC$19*AC23,Data!$C$1:$X$161,21,FALSE)*25,0) -> 7009725 | AH23: =AE23/AD23 -> 0.42548347 | AI23: =IF(AG23<0, IF(AF23<0,AF23/AG23,-10),IF(AF23<0,10,AG23/AF23)) -> 0.48544306
